package aginsun.mods.RiseOfMinecraft.WorldGen;

import java.util.Random;

import aginsun.mods.RiseOfMinecraft.Blocks.ModBlocks;

import net.minecraft.src.Block;
import net.minecraft.src.World;

public class WorldGenMainBuilding
{
    private World world;
    private Random rand;
    private int i;
    private int j;
    private int k;

    public WorldGenMainBuilding(World world1, int l, int i1, int j1)
    {
        world = world1;
        i = l;
        j = i1;
        k = j1;
    }
    
    public void WorldGen()
    {
    	generate();
    	generate2();
    	generate3();
    	
    	//Special block
		world.setBlock(i + 9, j + 1, k + 9, ModBlocks.BlockMainBuilding.blockID);
    }

	public void generate() 
	{
		world.setBlock(i + 0, j + 0, k + 0, 0);
		world.setBlock(i + 0, j + 0, k + 1, 0);
		world.setBlock(i + 0, j + 0, k + 2, 0);
		world.setBlock(i + 0, j + 0, k + 3, 0);
		world.setBlock(i + 0, j + 0, k + 4, 0);
		world.setBlock(i + 0, j + 0, k + 5, 0);
		world.setBlock(i + 0, j + 0, k + 6, 0);
		world.setBlock(i + 0, j + 0, k + 7, 0);
		world.setBlock(i + 0, j + 0, k + 8, 0);
		world.setBlock(i + 0, j + 0, k + 9, 0);
		world.setBlock(i + 0, j + 0, k + 10, 0);
		world.setBlock(i + 0, j + 0, k + 11, 0);
		world.setBlock(i + 0, j + 0, k + 12, 0);
		world.setBlock(i + 0, j + 0, k + 13, 0);
		world.setBlock(i + 0, j + 0, k + 14, 0);
		world.setBlock(i + 0, j + 0, k + 15, 0);
		world.setBlock(i + 0, j + 0, k + 16, 0);
		world.setBlock(i + 0, j + 0, k + 17, 0);
		world.setBlock(i + 0, j + 0, k + 18, 0);
		world.setBlock(i + 0, j + 1, k + 0, 0);
		world.setBlock(i + 0, j + 1, k + 1, 0);
		world.setBlock(i + 0, j + 1, k + 2, 0);
		world.setBlock(i + 0, j + 1, k + 3, 0);
		world.setBlock(i + 0, j + 1, k + 4, 0);
		world.setBlock(i + 0, j + 1, k + 5, 0);
		world.setBlock(i + 0, j + 1, k + 6, 0);
		world.setBlock(i + 0, j + 1, k + 7, 0);
		world.setBlock(i + 0, j + 1, k + 8, 0);
		world.setBlock(i + 0, j + 1, k + 9, 0);
		world.setBlock(i + 0, j + 1, k + 10, 0);
		world.setBlock(i + 0, j + 1, k + 11, 0);
		world.setBlock(i + 0, j + 1, k + 12, 0);
		world.setBlock(i + 0, j + 1, k + 13, 0);
		world.setBlock(i + 0, j + 1, k + 14, 0);
		world.setBlock(i + 0, j + 1, k + 15, 0);
		world.setBlock(i + 0, j + 1, k + 16, 0);
		world.setBlock(i + 0, j + 1, k + 17, 0);
		world.setBlock(i + 0, j + 1, k + 18, 0);
		world.setBlock(i + 0, j + 2, k + 0, 0);
		world.setBlock(i + 0, j + 2, k + 1, 0);
		world.setBlock(i + 0, j + 2, k + 2, 0);
		world.setBlock(i + 0, j + 2, k + 3, 0);
		world.setBlock(i + 0, j + 2, k + 4, 0);
		world.setBlock(i + 0, j + 2, k + 5, 0);
		world.setBlock(i + 0, j + 2, k + 6, 0);
		world.setBlock(i + 0, j + 2, k + 7, 0);
		world.setBlock(i + 0, j + 2, k + 8, 0);
		world.setBlock(i + 0, j + 2, k + 9, 0);
		world.setBlock(i + 0, j + 2, k + 10, 0);
		world.setBlock(i + 0, j + 2, k + 11, 0);
		world.setBlock(i + 0, j + 2, k + 12, 0);
		world.setBlock(i + 0, j + 2, k + 13, 0);
		world.setBlock(i + 0, j + 2, k + 14, 0);
		world.setBlock(i + 0, j + 2, k + 15, 0);
		world.setBlock(i + 0, j + 2, k + 16, 0);
		world.setBlock(i + 0, j + 2, k + 17, 0);
		world.setBlock(i + 0, j + 2, k + 18, 0);
		world.setBlock(i + 0, j + 3, k + 0, 0);
		world.setBlock(i + 0, j + 3, k + 1, 0);
		world.setBlock(i + 0, j + 3, k + 2, 0);
		world.setBlock(i + 0, j + 3, k + 3, 0);
		world.setBlock(i + 0, j + 3, k + 4, 0);
		world.setBlock(i + 0, j + 3, k + 5, 0);
		world.setBlock(i + 0, j + 3, k + 6, 0);
		world.setBlock(i + 0, j + 3, k + 7, 0);
		world.setBlock(i + 0, j + 3, k + 8, 0);
		world.setBlock(i + 0, j + 3, k + 9, 0);
		world.setBlock(i + 0, j + 3, k + 10, 0);
		world.setBlock(i + 0, j + 3, k + 11, 0);
		world.setBlock(i + 0, j + 3, k + 12, 0);
		world.setBlock(i + 0, j + 3, k + 13, 0);
		world.setBlock(i + 0, j + 3, k + 14, 0);
		world.setBlock(i + 0, j + 3, k + 15, 0);
		world.setBlock(i + 0, j + 3, k + 16, 0);
		world.setBlock(i + 0, j + 3, k + 17, 0);
		world.setBlock(i + 0, j + 3, k + 18, 0);
		world.setBlock(i + 0, j + 4, k + 0, 0);
		world.setBlock(i + 0, j + 4, k + 1, 0);
		world.setBlock(i + 0, j + 4, k + 2, 0);
		world.setBlock(i + 0, j + 4, k + 3, 0);
		world.setBlock(i + 0, j + 4, k + 4, 0);
		world.setBlock(i + 0, j + 4, k + 5, 0);
		world.setBlock(i + 0, j + 4, k + 6, 0);
		world.setBlock(i + 0, j + 4, k + 7, 0);
		world.setBlock(i + 0, j + 4, k + 8, 0);
		world.setBlock(i + 0, j + 4, k + 9, 0);
		world.setBlock(i + 0, j + 4, k + 10, 0);
		world.setBlock(i + 0, j + 4, k + 11, 0);
		world.setBlock(i + 0, j + 4, k + 12, 0);
		world.setBlock(i + 0, j + 4, k + 13, 0);
		world.setBlock(i + 0, j + 4, k + 14, 0);
		world.setBlock(i + 0, j + 4, k + 15, 0);
		world.setBlock(i + 0, j + 4, k + 16, 0);
		world.setBlock(i + 0, j + 4, k + 17, 0);
		world.setBlock(i + 0, j + 4, k + 18, 0);
		world.setBlock(i + 0, j + 5, k + 0, 0);
		world.setBlock(i + 0, j + 5, k + 1, 0);
		world.setBlock(i + 0, j + 5, k + 2, 0);
		world.setBlock(i + 0, j + 5, k + 3, 0);
		world.setBlock(i + 0, j + 5, k + 4, 0);
		world.setBlock(i + 0, j + 5, k + 5, 0);
		world.setBlock(i + 0, j + 5, k + 6, 0);
		world.setBlock(i + 0, j + 5, k + 7, 0);
		world.setBlock(i + 0, j + 5, k + 8, 0);
		world.setBlock(i + 0, j + 5, k + 9, 0);
		world.setBlock(i + 0, j + 5, k + 10, 0);
		world.setBlock(i + 0, j + 5, k + 11, 0);
		world.setBlock(i + 0, j + 5, k + 12, 0);
		world.setBlock(i + 0, j + 5, k + 13, 0);
		world.setBlock(i + 0, j + 5, k + 14, 0);
		world.setBlock(i + 0, j + 5, k + 15, 0);
		world.setBlock(i + 0, j + 5, k + 16, 0);
		world.setBlock(i + 0, j + 5, k + 17, 0);
		world.setBlock(i + 0, j + 5, k + 18, 0);
		world.setBlock(i + 0, j + 6, k + 0, 0);
		world.setBlock(i + 0, j + 6, k + 1, 0);
		world.setBlock(i + 0, j + 6, k + 2, 0);
		world.setBlock(i + 0, j + 6, k + 3, 0);
		world.setBlock(i + 0, j + 6, k + 4, 0);
		world.setBlock(i + 0, j + 6, k + 5, 0);
		world.setBlock(i + 0, j + 6, k + 6, 0);
		world.setBlock(i + 0, j + 6, k + 7, 0);
		world.setBlock(i + 0, j + 6, k + 8, 0);
		world.setBlock(i + 0, j + 6, k + 9, 0);
		world.setBlock(i + 0, j + 6, k + 10, 0);
		world.setBlock(i + 0, j + 6, k + 11, 0);
		world.setBlock(i + 0, j + 6, k + 12, 0);
		world.setBlock(i + 0, j + 6, k + 13, 0);
		world.setBlock(i + 0, j + 6, k + 14, 0);
		world.setBlock(i + 0, j + 6, k + 15, 0);
		world.setBlock(i + 0, j + 6, k + 16, 0);
		world.setBlock(i + 0, j + 6, k + 17, 0);
		world.setBlock(i + 0, j + 6, k + 18, 0);
		world.setBlock(i + 0, j + 7, k + 0, 0);
		world.setBlock(i + 0, j + 7, k + 1, 0);
		world.setBlock(i + 0, j + 7, k + 2, 0);
		world.setBlock(i + 0, j + 7, k + 3, 0);
		world.setBlock(i + 0, j + 7, k + 4, 0);
		world.setBlock(i + 0, j + 7, k + 5, 0);
		world.setBlock(i + 0, j + 7, k + 6, 0);
		world.setBlock(i + 0, j + 7, k + 7, 0);
		world.setBlock(i + 0, j + 7, k + 8, Block.stairsStoneBrickSmooth.blockID);
		world.setBlock(i + 0, j + 7, k + 9, Block.stairsStoneBrickSmooth.blockID);
		world.setBlock(i + 0, j + 7, k + 10, Block.stairsStoneBrickSmooth.blockID);
		world.setBlock(i + 0, j + 7, k + 11, 0);
		world.setBlock(i + 0, j + 7, k + 12, 0);
		world.setBlock(i + 0, j + 7, k + 13, 0);
		world.setBlock(i + 0, j + 7, k + 14, 0);
		world.setBlock(i + 0, j + 7, k + 15, 0);
		world.setBlock(i + 0, j + 7, k + 16, 0);
		world.setBlock(i + 0, j + 7, k + 17, 0);
		world.setBlock(i + 0, j + 7, k + 18, 0);
		world.setBlock(i + 0, j + 8, k + 0, 0);
		world.setBlock(i + 0, j + 8, k + 1, 0);
		world.setBlock(i + 0, j + 8, k + 2, 0);
		world.setBlock(i + 0, j + 8, k + 3, 0);
		world.setBlock(i + 0, j + 8, k + 4, 0);
		world.setBlock(i + 0, j + 8, k + 5, 0);
		world.setBlock(i + 0, j + 8, k + 6, 0);
		world.setBlock(i + 0, j + 8, k + 7, 0);
		world.setBlock(i + 0, j + 8, k + 8, 0);
		world.setBlock(i + 0, j + 8, k + 9, 0);
		world.setBlock(i + 0, j + 8, k + 10, 0);
		world.setBlock(i + 0, j + 8, k + 11, 0);
		world.setBlock(i + 0, j + 8, k + 12, 0);
		world.setBlock(i + 0, j + 8, k + 13, 0);
		world.setBlock(i + 0, j + 8, k + 14, 0);
		world.setBlock(i + 0, j + 8, k + 15, 0);
		world.setBlock(i + 0, j + 8, k + 16, 0);
		world.setBlock(i + 0, j + 8, k + 17, 0);
		world.setBlock(i + 0, j + 8, k + 18, 0);
		world.setBlock(i + 1, j + 0, k + 0, 0);
		world.setBlock(i + 1, j + 0, k + 1, 0);
		world.setBlock(i + 1, j + 0, k + 2, 0);
		world.setBlock(i + 1, j + 0, k + 3, 0);
		world.setBlock(i + 1, j + 0, k + 4, 0);
		world.setBlock(i + 1, j + 0, k + 5, 0);
		world.setBlock(i + 1, j + 0, k + 6, 0);
		world.setBlock(i + 1, j + 0, k + 7, 0);
		world.setBlock(i + 1, j + 0, k + 8, 0);
		world.setBlock(i + 1, j + 0, k + 9, 0);
		world.setBlock(i + 1, j + 0, k + 10, 0);
		world.setBlock(i + 1, j + 0, k + 11, 0);
		world.setBlock(i + 1, j + 0, k + 12, 0);
		world.setBlock(i + 1, j + 0, k + 13, 0);
		world.setBlock(i + 1, j + 0, k + 14, 0);
		world.setBlock(i + 1, j + 0, k + 15, 0);
		world.setBlock(i + 1, j + 0, k + 16, 0);
		world.setBlock(i + 1, j + 0, k + 17, 0);
		world.setBlock(i + 1, j + 0, k + 18, 0);
		world.setBlock(i + 1, j + 1, k + 0, 0);
		world.setBlock(i + 1, j + 1, k + 1, 0);
		world.setBlock(i + 1, j + 1, k + 2, 0);
		world.setBlock(i + 1, j + 1, k + 3, 0);
		world.setBlock(i + 1, j + 1, k + 4, 0);
		world.setBlock(i + 1, j + 1, k + 5, 0);
		world.setBlock(i + 1, j + 1, k + 6, 0);
		world.setBlock(i + 1, j + 1, k + 7, 0);
		world.setBlock(i + 1, j + 1, k + 8, 0);
		world.setBlock(i + 1, j + 1, k + 9, 0);
		world.setBlock(i + 1, j + 1, k + 10, 0);
		world.setBlock(i + 1, j + 1, k + 11, 0);
		world.setBlock(i + 1, j + 1, k + 12, 0);
		world.setBlock(i + 1, j + 1, k + 13, 0);
		world.setBlock(i + 1, j + 1, k + 14, 0);
		world.setBlock(i + 1, j + 1, k + 15, 0);
		world.setBlock(i + 1, j + 1, k + 16, 0);
		world.setBlock(i + 1, j + 1, k + 17, 0);
		world.setBlock(i + 1, j + 1, k + 18, 0);
		world.setBlock(i + 1, j + 2, k + 0, 0);
		world.setBlock(i + 1, j + 2, k + 1, 0);
		world.setBlock(i + 1, j + 2, k + 2, 0);
		world.setBlock(i + 1, j + 2, k + 3, 0);
		world.setBlock(i + 1, j + 2, k + 4, 0);
		world.setBlock(i + 1, j + 2, k + 5, 0);
		world.setBlock(i + 1, j + 2, k + 6, 0);
		world.setBlock(i + 1, j + 2, k + 7, 0);
		world.setBlock(i + 1, j + 2, k + 8, 0);
		world.setBlock(i + 1, j + 2, k + 9, 0);
		world.setBlock(i + 1, j + 2, k + 10, 0);
		world.setBlock(i + 1, j + 2, k + 11, 0);
		world.setBlock(i + 1, j + 2, k + 12, 0);
		world.setBlock(i + 1, j + 2, k + 13, 0);
		world.setBlock(i + 1, j + 2, k + 14, 0);
		world.setBlock(i + 1, j + 2, k + 15, 0);
		world.setBlock(i + 1, j + 2, k + 16, 0);
		world.setBlock(i + 1, j + 2, k + 17, 0);
		world.setBlock(i + 1, j + 2, k + 18, 0);
		world.setBlock(i + 1, j + 3, k + 0, 0);
		world.setBlock(i + 1, j + 3, k + 1, 0);
		world.setBlock(i + 1, j + 3, k + 2, 0);
		world.setBlock(i + 1, j + 3, k + 3, 0);
		world.setBlock(i + 1, j + 3, k + 4, 0);
		world.setBlock(i + 1, j + 3, k + 5, 0);
		world.setBlock(i + 1, j + 3, k + 6, 0);
		world.setBlock(i + 1, j + 3, k + 7, 0);
		world.setBlock(i + 1, j + 3, k + 8, 0);
		world.setBlock(i + 1, j + 3, k + 9, 0);
		world.setBlock(i + 1, j + 3, k + 10, 0);
		world.setBlock(i + 1, j + 3, k + 11, 0);
		world.setBlock(i + 1, j + 3, k + 12, 0);
		world.setBlock(i + 1, j + 3, k + 13, 0);
		world.setBlock(i + 1, j + 3, k + 14, 0);
		world.setBlock(i + 1, j + 3, k + 15, 0);
		world.setBlock(i + 1, j + 3, k + 16, 0);
		world.setBlock(i + 1, j + 3, k + 17, 0);
		world.setBlock(i + 1, j + 3, k + 18, 0);
		world.setBlock(i + 1, j + 4, k + 0, 0);
		world.setBlock(i + 1, j + 4, k + 1, 0);
		world.setBlock(i + 1, j + 4, k + 2, 0);
		world.setBlock(i + 1, j + 4, k + 3, 0);
		world.setBlock(i + 1, j + 4, k + 4, 0);
		world.setBlock(i + 1, j + 4, k + 5, 0);
		world.setBlock(i + 1, j + 4, k + 6, 0);
		world.setBlock(i + 1, j + 4, k + 7, 0);
		world.setBlock(i + 1, j + 4, k + 8, Block.stoneBrick.blockID);
		world.setBlock(i + 1, j + 4, k + 9, Block.stoneBrick.blockID);
		world.setBlock(i + 1, j + 4, k + 10, Block.stoneBrick.blockID);
		world.setBlock(i + 1, j + 4, k + 11, 0);
		world.setBlock(i + 1, j + 4, k + 12, 0);
		world.setBlock(i + 1, j + 4, k + 13, 0);
		world.setBlock(i + 1, j + 4, k + 14, 0);
		world.setBlock(i + 1, j + 4, k + 15, 0);
		world.setBlock(i + 1, j + 4, k + 16, 0);
		world.setBlock(i + 1, j + 4, k + 17, 0);
		world.setBlock(i + 1, j + 4, k + 18, 0);
		world.setBlock(i + 1, j + 5, k + 0, 0);
		world.setBlock(i + 1, j + 5, k + 1, 0);
		world.setBlock(i + 1, j + 5, k + 2, 0);
		world.setBlock(i + 1, j + 5, k + 3, 0);
		world.setBlock(i + 1, j + 5, k + 4, 0);
		world.setBlock(i + 1, j + 5, k + 5, 0);
		world.setBlock(i + 1, j + 5, k + 6, 0);
		world.setBlock(i + 1, j + 5, k + 7, 0);
		world.setBlock(i + 1, j + 5, k + 8, Block.thinGlass.blockID);
		world.setBlock(i + 1, j + 5, k + 9, 0);
		world.setBlock(i + 1, j + 5, k + 10, Block.thinGlass.blockID);
		world.setBlock(i + 1, j + 5, k + 11, 0);
		world.setBlock(i + 1, j + 5, k + 12, 0);
		world.setBlock(i + 1, j + 5, k + 13, 0);
		world.setBlock(i + 1, j + 5, k + 14, 0);
		world.setBlock(i + 1, j + 5, k + 15, 0);
		world.setBlock(i + 1, j + 5, k + 16, 0);
		world.setBlock(i + 1, j + 5, k + 17, 0);
		world.setBlock(i + 1, j + 5, k + 18, 0);
		world.setBlock(i + 1, j + 6, k + 0, 0);
		world.setBlock(i + 1, j + 6, k + 1, 0);
		world.setBlock(i + 1, j + 6, k + 2, 0);
		world.setBlock(i + 1, j + 6, k + 3, 0);
		world.setBlock(i + 1, j + 6, k + 4, 0);
		world.setBlock(i + 1, j + 6, k + 5, 0);
		world.setBlock(i + 1, j + 6, k + 6, 0);
		world.setBlock(i + 1, j + 6, k + 7, 0);
		world.setBlock(i + 1, j + 6, k + 8, Block.thinGlass.blockID);
		world.setBlock(i + 1, j + 6, k + 9, 0);
		world.setBlock(i + 1, j + 6, k + 10, Block.thinGlass.blockID);
		world.setBlock(i + 1, j + 6, k + 11, 0);
		world.setBlock(i + 1, j + 6, k + 12, 0);
		world.setBlock(i + 1, j + 6, k + 13, 0);
		world.setBlock(i + 1, j + 6, k + 14, 0);
		world.setBlock(i + 1, j + 6, k + 15, 0);
		world.setBlock(i + 1, j + 6, k + 16, 0);
		world.setBlock(i + 1, j + 6, k + 17, 0);
		world.setBlock(i + 1, j + 6, k + 18, 0);
		world.setBlock(i + 1, j + 7, k + 0, 0);
		world.setBlock(i + 1, j + 7, k + 1, 0);
		world.setBlock(i + 1, j + 7, k + 2, 0);
		world.setBlock(i + 1, j + 7, k + 3, 0);
		world.setBlock(i + 1, j + 7, k + 4, 0);
		world.setBlock(i + 1, j + 7, k + 5, 0);
		world.setBlock(i + 1, j + 7, k + 6, 0);
		world.setBlock(i + 1, j + 7, k + 7, 0);
		world.setBlockAndMetadata(i + 1, j + 7, k + 8, Block.stairsStoneBrickSmooth.blockID, 2);
		world.setBlock(i + 1, j + 7, k + 9, Block.stoneBrick.blockID);
		world.setBlockAndMetadata(i + 1, j + 7, k + 10, Block.stairsStoneBrickSmooth.blockID, 3);
		world.setBlock(i + 1, j + 7, k + 11, 0);
		world.setBlock(i + 1, j + 7, k + 12, 0);
		world.setBlock(i + 1, j + 7, k + 13, 0);
		world.setBlock(i + 1, j + 7, k + 14, 0);
		world.setBlock(i + 1, j + 7, k + 15, 0);
		world.setBlock(i + 1, j + 7, k + 16, 0);
		world.setBlock(i + 1, j + 7, k + 17, 0);
		world.setBlock(i + 1, j + 7, k + 18, 0);
		world.setBlock(i + 1, j + 8, k + 0, 0);
		world.setBlock(i + 1, j + 8, k + 1, 0);
		world.setBlock(i + 1, j + 8, k + 2, 0);
		world.setBlock(i + 1, j + 8, k + 3, 0);
		world.setBlock(i + 1, j + 8, k + 4, 0);
		world.setBlock(i + 1, j + 8, k + 5, 0);
		world.setBlock(i + 1, j + 8, k + 6, 0);
		world.setBlock(i + 1, j + 8, k + 7, 0);
		world.setBlock(i + 1, j + 8, k + 8, 0);
		world.setBlock(i + 1, j + 8, k + 9, 0);
		world.setBlock(i + 1, j + 8, k + 10, 0);
		world.setBlock(i + 1, j + 8, k + 11, 0);
		world.setBlock(i + 1, j + 8, k + 12, 0);
		world.setBlock(i + 1, j + 8, k + 13, 0);
		world.setBlock(i + 1, j + 8, k + 14, 0);
		world.setBlock(i + 1, j + 8, k + 15, 0);
		world.setBlock(i + 1, j + 8, k + 16, 0);
		world.setBlock(i + 1, j + 8, k + 17, 0);
		world.setBlock(i + 1, j + 8, k + 18, 0);
		world.setBlock(i + 2, j + 0, k + 0, 0);
		world.setBlock(i + 2, j + 0, k + 1, 0);
		world.setBlock(i + 2, j + 0, k + 2, 0);
		world.setBlock(i + 2, j + 0, k + 3, 0);
		world.setBlock(i + 2, j + 0, k + 4, 0);
		world.setBlock(i + 2, j + 0, k + 5, 0);
		world.setBlock(i + 2, j + 0, k + 6, 0);
		world.setBlock(i + 2, j + 0, k + 7, 0);
		world.setBlock(i + 2, j + 0, k + 8, 0);
		world.setBlock(i + 2, j + 0, k + 9, 0);
		world.setBlock(i + 2, j + 0, k + 10, 0);
		world.setBlock(i + 2, j + 0, k + 11, 0);
		world.setBlock(i + 2, j + 0, k + 12, 0);
		world.setBlock(i + 2, j + 0, k + 13, 0);
		world.setBlock(i + 2, j + 0, k + 14, 0);
		world.setBlock(i + 2, j + 0, k + 15, 0);
		world.setBlock(i + 2, j + 0, k + 16, 0);
		world.setBlock(i + 2, j + 0, k + 17, 0);
		world.setBlock(i + 2, j + 0, k + 18, 0);
		world.setBlock(i + 2, j + 1, k + 0, 0);
		world.setBlock(i + 2, j + 1, k + 1, 0);
		world.setBlock(i + 2, j + 1, k + 2, 0);
		world.setBlock(i + 2, j + 1, k + 3, 0);
		world.setBlock(i + 2, j + 1, k + 4, 0);
		world.setBlock(i + 2, j + 1, k + 5, 0);
		world.setBlock(i + 2, j + 1, k + 6, 0);
		world.setBlock(i + 2, j + 1, k + 7, 0);
		world.setBlock(i + 2, j + 1, k + 8, 0);
		world.setBlock(i + 2, j + 1, k + 9, 0);
		world.setBlock(i + 2, j + 1, k + 10, 0);
		world.setBlock(i + 2, j + 1, k + 11, 0);
		world.setBlock(i + 2, j + 1, k + 12, 0);
		world.setBlock(i + 2, j + 1, k + 13, 0);
		world.setBlock(i + 2, j + 1, k + 14, 0);
		world.setBlock(i + 2, j + 1, k + 15, 0);
		world.setBlock(i + 2, j + 1, k + 16, 0);
		world.setBlock(i + 2, j + 1, k + 17, 0);
		world.setBlock(i + 2, j + 1, k + 18, 0);
		world.setBlock(i + 2, j + 2, k + 0, 0);
		world.setBlock(i + 2, j + 2, k + 1, 0);
		world.setBlock(i + 2, j + 2, k + 2, 0);
		world.setBlock(i + 2, j + 2, k + 3, 0);
		world.setBlock(i + 2, j + 2, k + 4, 0);
		world.setBlock(i + 2, j + 2, k + 5, 0);
		world.setBlock(i + 2, j + 2, k + 6, 0);
		world.setBlock(i + 2, j + 2, k + 7, 0);
		world.setBlock(i + 2, j + 2, k + 8, 0);
		world.setBlock(i + 2, j + 2, k + 9, 0);
		world.setBlock(i + 2, j + 2, k + 10, 0);
		world.setBlock(i + 2, j + 2, k + 11, 0);
		world.setBlock(i + 2, j + 2, k + 12, 0);
		world.setBlock(i + 2, j + 2, k + 13, 0);
		world.setBlock(i + 2, j + 2, k + 14, 0);
		world.setBlock(i + 2, j + 2, k + 15, 0);
		world.setBlock(i + 2, j + 2, k + 16, 0);
		world.setBlock(i + 2, j + 2, k + 17, 0);
		world.setBlock(i + 2, j + 2, k + 18, 0);
		world.setBlock(i + 2, j + 3, k + 0, 0);
		world.setBlock(i + 2, j + 3, k + 1, 0);
		world.setBlock(i + 2, j + 3, k + 2, 0);
		world.setBlock(i + 2, j + 3, k + 3, 0);
		world.setBlock(i + 2, j + 3, k + 4, 0);
		world.setBlock(i + 2, j + 3, k + 5, 0);
		world.setBlock(i + 2, j + 3, k + 6, 0);
		world.setBlock(i + 2, j + 3, k + 7, 0);
		world.setBlock(i + 2, j + 3, k + 8, 0);
		world.setBlock(i + 2, j + 3, k + 9, 0);
		world.setBlock(i + 2, j + 3, k + 10, 0);
		world.setBlock(i + 2, j + 3, k + 11, 0);
		world.setBlock(i + 2, j + 3, k + 12, 0);
		world.setBlock(i + 2, j + 3, k + 13, 0);
		world.setBlock(i + 2, j + 3, k + 14, 0);
		world.setBlock(i + 2, j + 3, k + 15, 0);
		world.setBlock(i + 2, j + 3, k + 16, 0);
		world.setBlock(i + 2, j + 3, k + 17, 0);
		world.setBlock(i + 2, j + 3, k + 18, 0);
		world.setBlock(i + 2, j + 4, k + 0, 0);
		world.setBlock(i + 2, j + 4, k + 1, 0);
		world.setBlock(i + 2, j + 4, k + 2, 0);
		world.setBlock(i + 2, j + 4, k + 3, 0);
		world.setBlock(i + 2, j + 4, k + 4, 0);
		world.setBlock(i + 2, j + 4, k + 5, 0);
		world.setBlock(i + 2, j + 4, k + 6, 0);
		world.setBlock(i + 2, j + 4, k + 7, 0);
		world.setBlock(i + 2, j + 4, k + 8, Block.stoneBrick.blockID);
		world.setBlock(i + 2, j + 4, k + 9, Block.stoneBrick.blockID);
		world.setBlock(i + 2, j + 4, k + 10, Block.stoneBrick.blockID);
		world.setBlock(i + 2, j + 4, k + 11, 0);
		world.setBlock(i + 2, j + 4, k + 12, 0);
		world.setBlock(i + 2, j + 4, k + 13, 0);
		world.setBlock(i + 2, j + 4, k + 14, 0);
		world.setBlock(i + 2, j + 4, k + 15, 0);
		world.setBlock(i + 2, j + 4, k + 16, 0);
		world.setBlock(i + 2, j + 4, k + 17, 0);
		world.setBlock(i + 2, j + 4, k + 18, 0);
		world.setBlock(i + 2, j + 5, k + 0, 0);
		world.setBlock(i + 2, j + 5, k + 1, 0);
		world.setBlock(i + 2, j + 5, k + 2, 0);
		world.setBlock(i + 2, j + 5, k + 3, 0);
		world.setBlock(i + 2, j + 5, k + 4, 0);
		world.setBlock(i + 2, j + 5, k + 5, 0);
		world.setBlock(i + 2, j + 5, k + 6, 0);
		world.setBlock(i + 2, j + 5, k + 7, 0);
		world.setBlock(i + 2, j + 5, k + 8, Block.thinGlass.blockID);
		world.setBlock(i + 2, j + 5, k + 9, 0);
		world.setBlock(i + 2, j + 5, k + 10, Block.thinGlass.blockID);
		world.setBlock(i + 2, j + 5, k + 11, 0);
		world.setBlock(i + 2, j + 5, k + 12, 0);
		world.setBlock(i + 2, j + 5, k + 13, 0);
		world.setBlock(i + 2, j + 5, k + 14, 0);
		world.setBlock(i + 2, j + 5, k + 15, 0);
		world.setBlock(i + 2, j + 5, k + 16, 0);
		world.setBlock(i + 2, j + 5, k + 17, 0);
		world.setBlock(i + 2, j + 5, k + 18, 0);
		world.setBlock(i + 2, j + 6, k + 0, 0);
		world.setBlock(i + 2, j + 6, k + 1, 0);
		world.setBlock(i + 2, j + 6, k + 2, 0);
		world.setBlock(i + 2, j + 6, k + 3, 0);
		world.setBlock(i + 2, j + 6, k + 4, 0);
		world.setBlock(i + 2, j + 6, k + 5, 0);
		world.setBlock(i + 2, j + 6, k + 6, 0);
		world.setBlock(i + 2, j + 6, k + 7, 0);
		world.setBlock(i + 2, j + 6, k + 8, Block.thinGlass.blockID);
		world.setBlock(i + 2, j + 6, k + 9, 0);
		world.setBlock(i + 2, j + 6, k + 10, Block.thinGlass.blockID);
		world.setBlock(i + 2, j + 6, k + 11, 0);
		world.setBlock(i + 2, j + 6, k + 12, 0);
		world.setBlock(i + 2, j + 6, k + 13, 0);
		world.setBlock(i + 2, j + 6, k + 14, 0);
		world.setBlock(i + 2, j + 6, k + 15, 0);
		world.setBlock(i + 2, j + 6, k + 16, 0);
		world.setBlock(i + 2, j + 6, k + 17, 0);
		world.setBlock(i + 2, j + 6, k + 18, 0);
		world.setBlock(i + 2, j + 7, k + 0, 0);
		world.setBlock(i + 2, j + 7, k + 1, 0);
		world.setBlock(i + 2, j + 7, k + 2, 0);
		world.setBlock(i + 2, j + 7, k + 3, 0);
		world.setBlock(i + 2, j + 7, k + 4, 0);
		world.setBlock(i + 2, j + 7, k + 5, 0);
		world.setBlock(i + 2, j + 7, k + 6, 0);
		world.setBlock(i + 2, j + 7, k + 7, 0);
		world.setBlockAndMetadata(i + 2, j + 7, k + 8, Block.stairsStoneBrickSmooth.blockID, 2);
		world.setBlock(i + 2, j + 7, k + 9, Block.stoneBrick.blockID);
		world.setBlockAndMetadata(i + 2, j + 7, k + 10, Block.stairsStoneBrickSmooth.blockID, 3);
		world.setBlock(i + 2, j + 7, k + 11, 0);
		world.setBlock(i + 2, j + 7, k + 12, 0);
		world.setBlock(i + 2, j + 7, k + 13, 0);
		world.setBlock(i + 2, j + 7, k + 14, 0);
		world.setBlock(i + 2, j + 7, k + 15, 0);
		world.setBlock(i + 2, j + 7, k + 16, 0);
		world.setBlock(i + 2, j + 7, k + 17, 0);
		world.setBlock(i + 2, j + 7, k + 18, 0);
		world.setBlock(i + 2, j + 8, k + 0, 0);
		world.setBlock(i + 2, j + 8, k + 1, 0);
		world.setBlock(i + 2, j + 8, k + 2, 0);
		world.setBlock(i + 2, j + 8, k + 3, 0);
		world.setBlock(i + 2, j + 8, k + 4, 0);
		world.setBlock(i + 2, j + 8, k + 5, 0);
		world.setBlock(i + 2, j + 8, k + 6, 0);
		world.setBlock(i + 2, j + 8, k + 7, 0);
		world.setBlock(i + 2, j + 8, k + 8, 0);
		world.setBlock(i + 2, j + 8, k + 9, 0);
		world.setBlock(i + 2, j + 8, k + 10, 0);
		world.setBlock(i + 2, j + 8, k + 11, 0);
		world.setBlock(i + 2, j + 8, k + 12, 0);
		world.setBlock(i + 2, j + 8, k + 13, 0);
		world.setBlock(i + 2, j + 8, k + 14, 0);
		world.setBlock(i + 2, j + 8, k + 15, 0);
		world.setBlock(i + 2, j + 8, k + 16, 0);
		world.setBlock(i + 2, j + 8, k + 17, 0);
		world.setBlock(i + 2, j + 8, k + 18, 0);
		world.setBlock(i + 3, j + 0, k + 0, 0);
		world.setBlock(i + 3, j + 0, k + 1, 0);
		world.setBlock(i + 3, j + 0, k + 2, 0);
		world.setBlock(i + 3, j + 0, k + 3, 0);
		world.setBlock(i + 3, j + 0, k + 4, 0);
		world.setBlock(i + 3, j + 0, k + 5, 0);
		world.setBlock(i + 3, j + 0, k + 6, 0);
		world.setBlock(i + 3, j + 0, k + 7, 0);
		world.setBlock(i + 3, j + 0, k + 8, 0);
		world.setBlock(i + 3, j + 0, k + 9, 0);
		world.setBlock(i + 3, j + 0, k + 10, 0);
		world.setBlock(i + 3, j + 0, k + 11, 0);
		world.setBlock(i + 3, j + 0, k + 12, 0);
		world.setBlock(i + 3, j + 0, k + 13, 0);
		world.setBlock(i + 3, j + 0, k + 14, 0);
		world.setBlock(i + 3, j + 0, k + 15, 0);
		world.setBlock(i + 3, j + 0, k + 16, 0);
		world.setBlock(i + 3, j + 0, k + 17, 0);
		world.setBlock(i + 3, j + 0, k + 18, 0);
		world.setBlock(i + 3, j + 1, k + 0, 0);
		world.setBlock(i + 3, j + 1, k + 1, 0);
		world.setBlock(i + 3, j + 1, k + 2, 0);
		world.setBlock(i + 3, j + 1, k + 3, 0);
		world.setBlock(i + 3, j + 1, k + 4, 0);
		world.setBlock(i + 3, j + 1, k + 5, 0);
		world.setBlock(i + 3, j + 1, k + 6, 0);
		world.setBlock(i + 3, j + 1, k + 7, 0);
		world.setBlock(i + 3, j + 1, k + 8, 0);
		world.setBlock(i + 3, j + 1, k + 9, 0);
		world.setBlock(i + 3, j + 1, k + 10, 0);
		world.setBlock(i + 3, j + 1, k + 11, 0);
		world.setBlock(i + 3, j + 1, k + 12, 0);
		world.setBlock(i + 3, j + 1, k + 13, 0);
		world.setBlock(i + 3, j + 1, k + 14, 0);
		world.setBlock(i + 3, j + 1, k + 15, 0);
		world.setBlock(i + 3, j + 1, k + 16, 0);
		world.setBlock(i + 3, j + 1, k + 17, 0);
		world.setBlock(i + 3, j + 1, k + 18, 0);
		world.setBlock(i + 3, j + 2, k + 0, 0);
		world.setBlock(i + 3, j + 2, k + 1, 0);
		world.setBlock(i + 3, j + 2, k + 2, 0);
		world.setBlock(i + 3, j + 2, k + 3, 0);
		world.setBlock(i + 3, j + 2, k + 4, 0);
		world.setBlock(i + 3, j + 2, k + 5, 0);
		world.setBlock(i + 3, j + 2, k + 6, 0);
		world.setBlock(i + 3, j + 2, k + 7, 0);
		world.setBlock(i + 3, j + 2, k + 8, 0);
		world.setBlock(i + 3, j + 2, k + 9, 0);
		world.setBlock(i + 3, j + 2, k + 10, 0);
		world.setBlock(i + 3, j + 2, k + 11, 0);
		world.setBlock(i + 3, j + 2, k + 12, 0);
		world.setBlock(i + 3, j + 2, k + 13, 0);
		world.setBlock(i + 3, j + 2, k + 14, 0);
		world.setBlock(i + 3, j + 2, k + 15, 0);
		world.setBlock(i + 3, j + 2, k + 16, 0);
		world.setBlock(i + 3, j + 2, k + 17, 0);
		world.setBlock(i + 3, j + 2, k + 18, 0);
		world.setBlock(i + 3, j + 3, k + 0, 0);
		world.setBlock(i + 3, j + 3, k + 1, 0);
		world.setBlock(i + 3, j + 3, k + 2, 0);
		world.setBlock(i + 3, j + 3, k + 3, 0);
		world.setBlock(i + 3, j + 3, k + 4, 0);
		world.setBlock(i + 3, j + 3, k + 5, 0);
		world.setBlock(i + 3, j + 3, k + 6, 0);
		world.setBlock(i + 3, j + 3, k + 7, 0);
		world.setBlock(i + 3, j + 3, k + 8, 0);
		world.setBlock(i + 3, j + 3, k + 9, 0);
		world.setBlock(i + 3, j + 3, k + 10, 0);
		world.setBlock(i + 3, j + 3, k + 11, 0);
		world.setBlock(i + 3, j + 3, k + 12, 0);
		world.setBlock(i + 3, j + 3, k + 13, 0);
		world.setBlock(i + 3, j + 3, k + 14, 0);
		world.setBlock(i + 3, j + 3, k + 15, 0);
		world.setBlock(i + 3, j + 3, k + 16, 0);
		world.setBlock(i + 3, j + 3, k + 17, 0);
		world.setBlock(i + 3, j + 3, k + 18, 0);
		world.setBlock(i + 3, j + 4, k + 0, 0);
		world.setBlock(i + 3, j + 4, k + 1, 0);
		world.setBlock(i + 3, j + 4, k + 2, 0);
		world.setBlock(i + 3, j + 4, k + 3, 0);
		world.setBlock(i + 3, j + 4, k + 4, 0);
		world.setBlock(i + 3, j + 4, k + 5, 0);
		world.setBlock(i + 3, j + 4, k + 6, 0);
		world.setBlock(i + 3, j + 4, k + 7, 0);
		world.setBlock(i + 3, j + 4, k + 8, Block.stoneBrick.blockID);
		world.setBlock(i + 3, j + 4, k + 9, Block.stoneBrick.blockID);
		world.setBlock(i + 3, j + 4, k + 10, Block.stoneBrick.blockID);
		world.setBlock(i + 3, j + 4, k + 11, 0);
		world.setBlock(i + 3, j + 4, k + 12, 0);
		world.setBlock(i + 3, j + 4, k + 13, 0);
		world.setBlock(i + 3, j + 4, k + 14, 0);
		world.setBlock(i + 3, j + 4, k + 15, 0);
		world.setBlock(i + 3, j + 4, k + 16, 0);
		world.setBlock(i + 3, j + 4, k + 17, 0);
		world.setBlock(i + 3, j + 4, k + 18, 0);
		world.setBlock(i + 3, j + 5, k + 0, 0);
		world.setBlock(i + 3, j + 5, k + 1, 0);
		world.setBlock(i + 3, j + 5, k + 2, 0);
		world.setBlock(i + 3, j + 5, k + 3, 0);
		world.setBlock(i + 3, j + 5, k + 4, 0);
		world.setBlock(i + 3, j + 5, k + 5, 0);
		world.setBlock(i + 3, j + 5, k + 6, 0);
		world.setBlock(i + 3, j + 5, k + 7, 0);
		world.setBlock(i + 3, j + 5, k + 8, Block.thinGlass.blockID);
		world.setBlock(i + 3, j + 5, k + 9, 0);
		world.setBlock(i + 3, j + 5, k + 10, Block.thinGlass.blockID);
		world.setBlock(i + 3, j + 5, k + 11, 0);
		world.setBlock(i + 3, j + 5, k + 12, 0);
		world.setBlock(i + 3, j + 5, k + 13, 0);
		world.setBlock(i + 3, j + 5, k + 14, 0);
		world.setBlock(i + 3, j + 5, k + 15, 0);
		world.setBlock(i + 3, j + 5, k + 16, 0);
		world.setBlock(i + 3, j + 5, k + 17, 0);
		world.setBlock(i + 3, j + 5, k + 18, 0);
		world.setBlock(i + 3, j + 6, k + 0, 0);
		world.setBlock(i + 3, j + 6, k + 1, 0);
		world.setBlock(i + 3, j + 6, k + 2, 0);
		world.setBlock(i + 3, j + 6, k + 3, 0);
		world.setBlock(i + 3, j + 6, k + 4, 0);
		world.setBlock(i + 3, j + 6, k + 5, 0);
		world.setBlock(i + 3, j + 6, k + 6, 0);
		world.setBlock(i + 3, j + 6, k + 7, 0);
		world.setBlock(i + 3, j + 6, k + 8, Block.thinGlass.blockID);
		world.setBlock(i + 3, j + 6, k + 9, 0);
		world.setBlock(i + 3, j + 6, k + 10, Block.thinGlass.blockID);
		world.setBlock(i + 3, j + 6, k + 11, 0);
		world.setBlock(i + 3, j + 6, k + 12, 0);
		world.setBlock(i + 3, j + 6, k + 13, 0);
		world.setBlock(i + 3, j + 6, k + 14, 0);
		world.setBlock(i + 3, j + 6, k + 15, 0);
		world.setBlock(i + 3, j + 6, k + 16, 0);
		world.setBlock(i + 3, j + 6, k + 17, 0);
		world.setBlock(i + 3, j + 6, k + 18, 0);
		world.setBlock(i + 3, j + 7, k + 0, 0);
		world.setBlock(i + 3, j + 7, k + 1, 0);
		world.setBlock(i + 3, j + 7, k + 2, 0);
		world.setBlock(i + 3, j + 7, k + 3, 0);
		world.setBlock(i + 3, j + 7, k + 4, 0);
		world.setBlock(i + 3, j + 7, k + 5, 0);
		world.setBlock(i + 3, j + 7, k + 6, 0);
		world.setBlock(i + 3, j + 7, k + 7, 0);
		world.setBlockAndMetadata(i + 3, j + 7, k + 8, Block.stairsStoneBrickSmooth.blockID, 2);
		world.setBlock(i + 3, j + 7, k + 9, Block.stoneBrick.blockID);
		world.setBlockAndMetadata(i + 3, j + 7, k + 10, Block.stairsStoneBrickSmooth.blockID, 3);
		world.setBlock(i + 3, j + 7, k + 11, 0);
		world.setBlock(i + 3, j + 7, k + 12, 0);
		world.setBlock(i + 3, j + 7, k + 13, 0);
		world.setBlock(i + 3, j + 7, k + 14, 0);
		world.setBlock(i + 3, j + 7, k + 15, 0);
		world.setBlock(i + 3, j + 7, k + 16, 0);
		world.setBlock(i + 3, j + 7, k + 17, 0);
		world.setBlock(i + 3, j + 7, k + 18, 0);
		world.setBlock(i + 3, j + 8, k + 0, 0);
		world.setBlock(i + 3, j + 8, k + 1, 0);
		world.setBlock(i + 3, j + 8, k + 2, 0);
		world.setBlock(i + 3, j + 8, k + 3, 0);
		world.setBlock(i + 3, j + 8, k + 4, 0);
		world.setBlock(i + 3, j + 8, k + 5, 0);
		world.setBlock(i + 3, j + 8, k + 6, 0);
		world.setBlock(i + 3, j + 8, k + 7, 0);
		world.setBlock(i + 3, j + 8, k + 8, 0);
		world.setBlock(i + 3, j + 8, k + 9, 0);
		world.setBlock(i + 3, j + 8, k + 10, 0);
		world.setBlock(i + 3, j + 8, k + 11, 0);
		world.setBlock(i + 3, j + 8, k + 12, 0);
		world.setBlock(i + 3, j + 8, k + 13, 0);
		world.setBlock(i + 3, j + 8, k + 14, 0);
		world.setBlock(i + 3, j + 8, k + 15, 0);
		world.setBlock(i + 3, j + 8, k + 16, 0);
		world.setBlock(i + 3, j + 8, k + 17, 0);
		world.setBlock(i + 3, j + 8, k + 18, 0);
		world.setBlock(i + 4, j + 0, k + 0, 0);
		world.setBlock(i + 4, j + 0, k + 1, 0);
		world.setBlock(i + 4, j + 0, k + 2, 0);
		world.setBlock(i + 4, j + 0, k + 3, 0);
		world.setBlock(i + 4, j + 0, k + 4, 0);
		world.setBlock(i + 4, j + 0, k + 5, 0);
		world.setBlock(i + 4, j + 0, k + 6, 0);
		world.setBlock(i + 4, j + 0, k + 7, 0);
		world.setBlock(i + 4, j + 0, k + 8, 0);
		world.setBlock(i + 4, j + 0, k + 9, 0);
		world.setBlock(i + 4, j + 0, k + 10, 0);
		world.setBlock(i + 4, j + 0, k + 11, 0);
		world.setBlock(i + 4, j + 0, k + 12, 0);
		world.setBlock(i + 4, j + 0, k + 13, 0);
		world.setBlock(i + 4, j + 0, k + 14, 0);
		world.setBlock(i + 4, j + 0, k + 15, 0);
		world.setBlock(i + 4, j + 0, k + 16, 0);
		world.setBlock(i + 4, j + 0, k + 17, 0);
		world.setBlock(i + 4, j + 0, k + 18, 0);
		world.setBlock(i + 4, j + 1, k + 0, 0);
		world.setBlock(i + 4, j + 1, k + 1, 0);
		world.setBlock(i + 4, j + 1, k + 2, 0);
		world.setBlock(i + 4, j + 1, k + 3, 0);
		world.setBlock(i + 4, j + 1, k + 4, 0);
		world.setBlock(i + 4, j + 1, k + 5, 0);
		world.setBlock(i + 4, j + 1, k + 6, 0);
		world.setBlock(i + 4, j + 1, k + 7, 0);
		world.setBlock(i + 4, j + 1, k + 8, 0);
		world.setBlock(i + 4, j + 1, k + 9, 0);
		world.setBlock(i + 4, j + 1, k + 10, 0);
		world.setBlock(i + 4, j + 1, k + 11, 0);
		world.setBlock(i + 4, j + 1, k + 12, 0);
		world.setBlock(i + 4, j + 1, k + 13, 0);
		world.setBlock(i + 4, j + 1, k + 14, 0);
		world.setBlock(i + 4, j + 1, k + 15, 0);
		world.setBlock(i + 4, j + 1, k + 16, 0);
		world.setBlock(i + 4, j + 1, k + 17, 0);
		world.setBlock(i + 4, j + 1, k + 18, 0);
		world.setBlock(i + 4, j + 2, k + 0, 0);
		world.setBlock(i + 4, j + 2, k + 1, 0);
		world.setBlock(i + 4, j + 2, k + 2, 0);
		world.setBlock(i + 4, j + 2, k + 3, 0);
		world.setBlock(i + 4, j + 2, k + 4, 0);
		world.setBlock(i + 4, j + 2, k + 5, 0);
		world.setBlock(i + 4, j + 2, k + 6, 0);
		world.setBlock(i + 4, j + 2, k + 7, 0);
		world.setBlock(i + 4, j + 2, k + 8, 0);
		world.setBlock(i + 4, j + 2, k + 9, 0);
		world.setBlock(i + 4, j + 2, k + 10, 0);
		world.setBlock(i + 4, j + 2, k + 11, 0);
		world.setBlock(i + 4, j + 2, k + 12, 0);
		world.setBlock(i + 4, j + 2, k + 13, 0);
		world.setBlock(i + 4, j + 2, k + 14, 0);
		world.setBlock(i + 4, j + 2, k + 15, 0);
		world.setBlock(i + 4, j + 2, k + 16, 0);
		world.setBlock(i + 4, j + 2, k + 17, 0);
		world.setBlock(i + 4, j + 2, k + 18, 0);
		world.setBlock(i + 4, j + 3, k + 0, 0);
		world.setBlock(i + 4, j + 3, k + 1, 0);
		world.setBlock(i + 4, j + 3, k + 2, 0);
		world.setBlock(i + 4, j + 3, k + 3, 0);
		world.setBlock(i + 4, j + 3, k + 4, 0);
		world.setBlock(i + 4, j + 3, k + 5, 0);
		world.setBlock(i + 4, j + 3, k + 6, 0);
		world.setBlock(i + 4, j + 3, k + 7, 0);
		world.setBlock(i + 4, j + 3, k + 8, 0);
		world.setBlock(i + 4, j + 3, k + 9, 0);
		world.setBlock(i + 4, j + 3, k + 10, 0);
		world.setBlock(i + 4, j + 3, k + 11, 0);
		world.setBlock(i + 4, j + 3, k + 12, 0);
		world.setBlock(i + 4, j + 3, k + 13, 0);
		world.setBlock(i + 4, j + 3, k + 14, 0);
		world.setBlock(i + 4, j + 3, k + 15, 0);
		world.setBlock(i + 4, j + 3, k + 16, 0);
		world.setBlock(i + 4, j + 3, k + 17, 0);
		world.setBlock(i + 4, j + 3, k + 18, 0);
		world.setBlock(i + 4, j + 4, k + 0, 0);
		world.setBlock(i + 4, j + 4, k + 1, 0);
		world.setBlock(i + 4, j + 4, k + 2, 0);
		world.setBlock(i + 4, j + 4, k + 3, 0);
		world.setBlock(i + 4, j + 4, k + 4, 0);
		world.setBlock(i + 4, j + 4, k + 5, 0);
		world.setBlock(i + 4, j + 4, k + 6, 0);
		world.setBlock(i + 4, j + 4, k + 7, 0);
		world.setBlock(i + 4, j + 4, k + 8, Block.stoneBrick.blockID);
		world.setBlock(i + 4, j + 4, k + 9, Block.stoneBrick.blockID);
		world.setBlock(i + 4, j + 4, k + 10, Block.stoneBrick.blockID);
		world.setBlock(i + 4, j + 4, k + 11, 0);
		world.setBlock(i + 4, j + 4, k + 12, 0);
		world.setBlock(i + 4, j + 4, k + 13, 0);
		world.setBlock(i + 4, j + 4, k + 14, 0);
		world.setBlock(i + 4, j + 4, k + 15, 0);
		world.setBlock(i + 4, j + 4, k + 16, 0);
		world.setBlock(i + 4, j + 4, k + 17, 0);
		world.setBlock(i + 4, j + 4, k + 18, 0);
		world.setBlock(i + 4, j + 5, k + 0, 0);
		world.setBlock(i + 4, j + 5, k + 1, 0);
		world.setBlock(i + 4, j + 5, k + 2, 0);
		world.setBlock(i + 4, j + 5, k + 3, 0);
		world.setBlock(i + 4, j + 5, k + 4, 0);
		world.setBlock(i + 4, j + 5, k + 5, 0);
		world.setBlock(i + 4, j + 5, k + 6, 0);
		world.setBlock(i + 4, j + 5, k + 7, 0);
		world.setBlock(i + 4, j + 5, k + 8, Block.thinGlass.blockID);
		world.setBlock(i + 4, j + 5, k + 9, 0);
		world.setBlock(i + 4, j + 5, k + 10, Block.thinGlass.blockID);
		world.setBlock(i + 4, j + 5, k + 11, 0);
		world.setBlock(i + 4, j + 5, k + 12, 0);
		world.setBlock(i + 4, j + 5, k + 13, 0);
		world.setBlock(i + 4, j + 5, k + 14, 0);
		world.setBlock(i + 4, j + 5, k + 15, 0);
		world.setBlock(i + 4, j + 5, k + 16, 0);
		world.setBlock(i + 4, j + 5, k + 17, 0);
		world.setBlock(i + 4, j + 5, k + 18, 0);
		world.setBlock(i + 4, j + 6, k + 0, 0);
		world.setBlock(i + 4, j + 6, k + 1, 0);
		world.setBlock(i + 4, j + 6, k + 2, 0);
		world.setBlock(i + 4, j + 6, k + 3, 0);
		world.setBlock(i + 4, j + 6, k + 4, 0);
		world.setBlock(i + 4, j + 6, k + 5, 0);
		world.setBlock(i + 4, j + 6, k + 6, 0);
		world.setBlock(i + 4, j + 6, k + 7, 0);
		world.setBlock(i + 4, j + 6, k + 8, Block.thinGlass.blockID);
		world.setBlock(i + 4, j + 6, k + 9, 0);
		world.setBlock(i + 4, j + 6, k + 10, Block.thinGlass.blockID);
		world.setBlock(i + 4, j + 6, k + 11, 0);
		world.setBlock(i + 4, j + 6, k + 12, 0);
		world.setBlock(i + 4, j + 6, k + 13, 0);
		world.setBlock(i + 4, j + 6, k + 14, 0);
		world.setBlock(i + 4, j + 6, k + 15, 0);
		world.setBlock(i + 4, j + 6, k + 16, 0);
		world.setBlock(i + 4, j + 6, k + 17, 0);
		world.setBlock(i + 4, j + 6, k + 18, 0);
		world.setBlock(i + 4, j + 7, k + 0, 0);
		world.setBlock(i + 4, j + 7, k + 1, 0);
		world.setBlock(i + 4, j + 7, k + 2, 0);
		world.setBlock(i + 4, j + 7, k + 3, 0);
		world.setBlock(i + 4, j + 7, k + 4, 0);
		world.setBlock(i + 4, j + 7, k + 5, 0);
		world.setBlock(i + 4, j + 7, k + 6, 0);
		world.setBlock(i + 4, j + 7, k + 7, 0);
		world.setBlockAndMetadata(i + 4, j + 7, k + 8, Block.stairsStoneBrickSmooth.blockID, 2);
		world.setBlock(i + 4, j + 7, k + 9, Block.stoneBrick.blockID);
		world.setBlockAndMetadata(i + 4, j + 7, k + 10, Block.stairsStoneBrickSmooth.blockID, 3);
		world.setBlock(i + 4, j + 7, k + 11, 0);
		world.setBlock(i + 4, j + 7, k + 12, 0);
		world.setBlock(i + 4, j + 7, k + 13, 0);
		world.setBlock(i + 4, j + 7, k + 14, 0);
		world.setBlock(i + 4, j + 7, k + 15, 0);
		world.setBlock(i + 4, j + 7, k + 16, 0);
		world.setBlock(i + 4, j + 7, k + 17, 0);
		world.setBlock(i + 4, j + 7, k + 18, 0);
		world.setBlock(i + 4, j + 8, k + 0, 0);
		world.setBlock(i + 4, j + 8, k + 1, 0);
		world.setBlock(i + 4, j + 8, k + 2, 0);
		world.setBlock(i + 4, j + 8, k + 3, 0);
		world.setBlock(i + 4, j + 8, k + 4, 0);
		world.setBlock(i + 4, j + 8, k + 5, 0);
		world.setBlock(i + 4, j + 8, k + 6, 0);
		world.setBlock(i + 4, j + 8, k + 7, 0);
		world.setBlock(i + 4, j + 8, k + 8, 0);
		world.setBlock(i + 4, j + 8, k + 9, 0);
		world.setBlock(i + 4, j + 8, k + 10, 0);
		world.setBlock(i + 4, j + 8, k + 11, 0);
		world.setBlock(i + 4, j + 8, k + 12, 0);
		world.setBlock(i + 4, j + 8, k + 13, 0);
		world.setBlock(i + 4, j + 8, k + 14, 0);
		world.setBlock(i + 4, j + 8, k + 15, 0);
		world.setBlock(i + 4, j + 8, k + 16, 0);
		world.setBlock(i + 4, j + 8, k + 17, 0);
		world.setBlock(i + 4, j + 8, k + 18, 0);
		world.setBlock(i + 5, j + 0, k + 0, 0);
		world.setBlock(i + 5, j + 0, k + 1, 0);
		world.setBlock(i + 5, j + 0, k + 2, 0);
		world.setBlock(i + 5, j + 0, k + 3, 0);
		world.setBlock(i + 5, j + 0, k + 4, 0);
		world.setBlock(i + 5, j + 0, k + 5, Block.grass.blockID);
		world.setBlock(i + 5, j + 0, k + 6, Block.grass.blockID);
		world.setBlock(i + 5, j + 0, k + 7, Block.grass.blockID);
		world.setBlock(i + 5, j + 0, k + 8, Block.grass.blockID);
		world.setBlock(i + 5, j + 0, k + 9, Block.grass.blockID);
		world.setBlock(i + 5, j + 0, k + 10, Block.grass.blockID);
		world.setBlock(i + 5, j + 0, k + 11, Block.grass.blockID);
		world.setBlock(i + 5, j + 0, k + 12, Block.grass.blockID);
		world.setBlock(i + 5, j + 0, k + 13, Block.grass.blockID);
		world.setBlock(i + 5, j + 0, k + 14, 0);
		world.setBlock(i + 5, j + 0, k + 15, 0);
		world.setBlock(i + 5, j + 0, k + 16, 0);
		world.setBlock(i + 5, j + 0, k + 17, 0);
		world.setBlock(i + 5, j + 0, k + 18, 0);
		world.setBlock(i + 5, j + 1, k + 0, 0);
		world.setBlock(i + 5, j + 1, k + 1, 0);
		world.setBlock(i + 5, j + 1, k + 2, 0);
		world.setBlock(i + 5, j + 1, k + 3, 0);
		world.setBlock(i + 5, j + 1, k + 4, 0);
		world.setBlock(i + 5, j + 1, k + 5, 0);
		world.setBlock(i + 5, j + 1, k + 7, 0);
		world.setBlock(i + 5, j + 1, k + 8, 0);
		world.setBlock(i + 5, j + 1, k + 9, 0);
		world.setBlock(i + 5, j + 1, k + 10, 0);
		world.setBlock(i + 5, j + 1, k + 11, 0);
		world.setBlock(i + 5, j + 1, k + 13, 0);
		world.setBlock(i + 5, j + 1, k + 14, 0);
		world.setBlock(i + 5, j + 1, k + 15, 0);
		world.setBlock(i + 5, j + 1, k + 16, 0);
		world.setBlock(i + 5, j + 1, k + 17, 0);
		world.setBlock(i + 5, j + 1, k + 18, 0);
		world.setBlock(i + 5, j + 2, k + 0, 0);
		world.setBlock(i + 5, j + 2, k + 1, 0);
		world.setBlock(i + 5, j + 2, k + 2, 0);
		world.setBlock(i + 5, j + 2, k + 3, 0);
		world.setBlock(i + 5, j + 2, k + 4, 0);
		world.setBlock(i + 5, j + 2, k + 5, 0);
		world.setBlock(i + 5, j + 2, k + 7, 0);
		world.setBlock(i + 5, j + 2, k + 8, 0);
		world.setBlock(i + 5, j + 2, k + 9, 0);
		world.setBlock(i + 5, j + 2, k + 10, 0);
		world.setBlock(i + 5, j + 2, k + 11, 0);
		world.setBlock(i + 5, j + 2, k + 13, 0);
		world.setBlock(i + 5, j + 2, k + 14, 0);
		world.setBlock(i + 5, j + 2, k + 15, 0);
		world.setBlock(i + 5, j + 2, k + 16, 0);
		world.setBlock(i + 5, j + 2, k + 17, 0);
		world.setBlock(i + 5, j + 2, k + 18, 0);
		world.setBlock(i + 5, j + 3, k + 0, 0);
		world.setBlock(i + 5, j + 3, k + 1, 0);
		world.setBlock(i + 5, j + 3, k + 2, 0);
		world.setBlock(i + 5, j + 3, k + 3, 0);
		world.setBlock(i + 5, j + 3, k + 4, 0);
		world.setBlock(i + 5, j + 3, k + 5, 0);
		world.setBlock(i + 5, j + 3, k + 7, 0);
		world.setBlock(i + 5, j + 3, k + 8, 0);
		world.setBlock(i + 5, j + 3, k + 9, 0);
		world.setBlock(i + 5, j + 3, k + 10, 0);
		world.setBlock(i + 5, j + 3, k + 11, 0);
		world.setBlock(i + 5, j + 3, k + 13, 0);
		world.setBlock(i + 5, j + 3, k + 14, 0);
		world.setBlock(i + 5, j + 3, k + 15, 0);
		world.setBlock(i + 5, j + 3, k + 16, 0);
		world.setBlock(i + 5, j + 3, k + 17, 0);
		world.setBlock(i + 5, j + 3, k + 18, 0);
		world.setBlock(i + 5, j + 4, k + 0, 0);
		world.setBlock(i + 5, j + 4, k + 1, 0);
		world.setBlock(i + 5, j + 4, k + 2, 0);
		world.setBlock(i + 5, j + 4, k + 3, 0);
		world.setBlock(i + 5, j + 4, k + 4, 0);
		world.setBlock(i + 5, j + 4, k + 5, 0);
		world.setBlock(i + 5, j + 4, k + 7, 0);
		world.setBlock(i + 5, j + 4, k + 8, Block.stoneBrick.blockID);
		world.setBlock(i + 5, j + 4, k + 9, Block.stoneBrick.blockID);
		world.setBlock(i + 5, j + 4, k + 10, Block.stoneBrick.blockID);
		world.setBlock(i + 5, j + 4, k + 11, 0);
		world.setBlock(i + 5, j + 4, k + 13, 0);
		world.setBlock(i + 5, j + 4, k + 14, 0);
		world.setBlock(i + 5, j + 4, k + 15, 0);
		world.setBlock(i + 5, j + 4, k + 16, 0);
		world.setBlock(i + 5, j + 4, k + 17, 0);
		world.setBlock(i + 5, j + 4, k + 18, 0);
		world.setBlock(i + 5, j + 5, k + 0, 0);
		world.setBlock(i + 5, j + 5, k + 1, 0);
		world.setBlock(i + 5, j + 5, k + 2, 0);
		world.setBlock(i + 5, j + 5, k + 3, 0);
		world.setBlock(i + 5, j + 5, k + 4, 0);
		world.setBlock(i + 5, j + 5, k + 5, 0);
		world.setBlock(i + 5, j + 5, k + 6, 0);
		world.setBlock(i + 5, j + 5, k + 7, 0);
		world.setBlock(i + 5, j + 5, k + 8, Block.thinGlass.blockID);
		world.setBlock(i + 5, j + 5, k + 9, 0);
		world.setBlock(i + 5, j + 5, k + 10, Block.thinGlass.blockID);
		world.setBlock(i + 5, j + 5, k + 11, 0);
		world.setBlock(i + 5, j + 5, k + 12, 0);
		world.setBlock(i + 5, j + 5, k + 13, 0);
		world.setBlock(i + 5, j + 5, k + 14, 0);
		world.setBlock(i + 5, j + 5, k + 15, 0);
		world.setBlock(i + 5, j + 5, k + 16, 0);
		world.setBlock(i + 5, j + 5, k + 17, 0);
		world.setBlock(i + 5, j + 5, k + 18, 0);
		world.setBlock(i + 5, j + 6, k + 0, 0);
		world.setBlock(i + 5, j + 6, k + 1, 0);
		world.setBlock(i + 5, j + 6, k + 2, 0);
		world.setBlock(i + 5, j + 6, k + 3, 0);
		world.setBlock(i + 5, j + 6, k + 4, 0);
		world.setBlock(i + 5, j + 6, k + 5, 0);
		world.setBlock(i + 5, j + 6, k + 6, 0);
		world.setBlock(i + 5, j + 6, k + 7, 0);
		world.setBlock(i + 5, j + 6, k + 8, Block.thinGlass.blockID);
		world.setBlock(i + 5, j + 6, k + 9, 0);
		world.setBlock(i + 5, j + 6, k + 10, Block.thinGlass.blockID);
		world.setBlock(i + 5, j + 6, k + 11, 0);
		world.setBlock(i + 5, j + 6, k + 12, 0);
		world.setBlock(i + 5, j + 6, k + 13, 0);
		world.setBlock(i + 5, j + 6, k + 14, 0);
		world.setBlock(i + 5, j + 6, k + 15, 0);
		world.setBlock(i + 5, j + 6, k + 16, 0);
		world.setBlock(i + 5, j + 6, k + 17, 0);
		world.setBlock(i + 5, j + 6, k + 18, 0);
		world.setBlock(i + 5, j + 7, k + 0, 0);
		world.setBlock(i + 5, j + 7, k + 1, 0);
		world.setBlock(i + 5, j + 7, k + 2, 0);
		world.setBlock(i + 5, j + 7, k + 3, 0);
		world.setBlock(i + 5, j + 7, k + 4, 0);
		world.setBlock(i + 5, j + 7, k + 5, 0);
		world.setBlock(i + 5, j + 7, k + 6, 0);
		world.setBlock(i + 5, j + 7, k + 7, 0);
		world.setBlockAndMetadata(i + 5, j + 7, k + 8, Block.stairsStoneBrickSmooth.blockID, 2);
		world.setBlock(i + 5, j + 7, k + 9, Block.stoneBrick.blockID);
		world.setBlockAndMetadata(i + 5, j + 7, k + 10, Block.stairsStoneBrickSmooth.blockID, 3);
		world.setBlock(i + 5, j + 7, k + 11, 0);
		world.setBlock(i + 5, j + 7, k + 12, 0);
		world.setBlock(i + 5, j + 7, k + 13, 0);
		world.setBlock(i + 5, j + 7, k + 14, 0);
		world.setBlock(i + 5, j + 7, k + 15, 0);
		world.setBlock(i + 5, j + 7, k + 16, 0);
		world.setBlock(i + 5, j + 7, k + 17, 0);
		world.setBlock(i + 5, j + 7, k + 18, 0);
		world.setBlock(i + 5, j + 8, k + 0, 0);
		world.setBlock(i + 5, j + 8, k + 1, 0);
		world.setBlock(i + 5, j + 8, k + 2, 0);
		world.setBlock(i + 5, j + 8, k + 3, 0);
		world.setBlock(i + 5, j + 8, k + 4, 0);
		world.setBlock(i + 5, j + 8, k + 5, 0);
		world.setBlock(i + 5, j + 8, k + 6, 0);
		world.setBlock(i + 5, j + 8, k + 7, 0);
		world.setBlock(i + 5, j + 8, k + 8, 0);
		world.setBlock(i + 5, j + 8, k + 9, 0);
		world.setBlock(i + 5, j + 8, k + 10, 0);
		world.setBlock(i + 5, j + 8, k + 11, 0);
		world.setBlock(i + 5, j + 8, k + 12, 0);
		world.setBlock(i + 5, j + 8, k + 13, 0);
		world.setBlock(i + 5, j + 8, k + 14, 0);
		world.setBlock(i + 5, j + 8, k + 15, 0);
		world.setBlock(i + 5, j + 8, k + 16, 0);
		world.setBlock(i + 5, j + 8, k + 17, 0);
		world.setBlock(i + 5, j + 8, k + 18, 0);
		world.setBlock(i + 6, j + 0, k + 0, 0);
		world.setBlock(i + 6, j + 0, k + 1, 0);
		world.setBlock(i + 6, j + 0, k + 2, 0);
		world.setBlock(i + 6, j + 0, k + 3, 0);
		world.setBlock(i + 6, j + 0, k + 4, 0);
		world.setBlock(i + 6, j + 0, k + 5, Block.grass.blockID);
		world.setBlock(i + 6, j + 0, k + 6, Block.stone.blockID);
		world.setBlock(i + 6, j + 0, k + 7, Block.dirt.blockID);
		world.setBlock(i + 6, j + 0, k + 8, Block.stone.blockID);
		world.setBlock(i + 6, j + 0, k + 9, Block.grass.blockID);
		world.setBlock(i + 6, j + 0, k + 10, Block.stone.blockID);
		world.setBlock(i + 6, j + 0, k + 11, Block.dirt.blockID);
		world.setBlock(i + 6, j + 0, k + 12, Block.stone.blockID);
		world.setBlock(i + 6, j + 0, k + 13, Block.grass.blockID);
		world.setBlock(i + 6, j + 0, k + 14, 0);
		world.setBlock(i + 6, j + 0, k + 15, 0);
		world.setBlock(i + 6, j + 0, k + 16, 0);
		world.setBlock(i + 6, j + 0, k + 17, 0);
		world.setBlock(i + 6, j + 0, k + 18, 0);
		world.setBlock(i + 6, j + 1, k + 0, 0);
		world.setBlock(i + 6, j + 1, k + 1, 0);
		world.setBlock(i + 6, j + 1, k + 2, 0);
		world.setBlock(i + 6, j + 1, k + 3, 0);
		world.setBlock(i + 6, j + 1, k + 4, 0);
		world.setBlock(i + 6, j + 1, k + 5, 0);
		world.setBlock(i + 6, j + 1, k + 6, Block.stoneBrick.blockID);
		world.setBlock(i + 6, j + 1, k + 7, Block.stoneBrick.blockID);
		world.setBlock(i + 6, j + 1, k + 8, 0);
		world.setBlock(i + 6, j + 1, k + 9, 0);
		world.setBlock(i + 6, j + 1, k + 10, 0);
		world.setBlock(i + 6, j + 1, k + 11, Block.stoneBrick.blockID);
		world.setBlock(i + 6, j + 1, k + 12, Block.stoneBrick.blockID);
		world.setBlock(i + 6, j + 1, k + 13, 0);
		world.setBlock(i + 6, j + 1, k + 14, 0);
		world.setBlock(i + 6, j + 1, k + 15, 0);
		world.setBlock(i + 6, j + 1, k + 16, 0);
		world.setBlock(i + 6, j + 1, k + 17, 0);
		world.setBlock(i + 6, j + 1, k + 18, 0);
		world.setBlock(i + 6, j + 2, k + 0, 0);
		world.setBlock(i + 6, j + 2, k + 1, 0);
		world.setBlock(i + 6, j + 2, k + 2, 0);
		world.setBlock(i + 6, j + 2, k + 3, 0);
		world.setBlock(i + 6, j + 2, k + 4, 0);
		world.setBlock(i + 6, j + 2, k + 5, 0);
		world.setBlock(i + 6, j + 2, k + 6, Block.stoneBrick.blockID);
		world.setBlock(i + 6, j + 2, k + 7, Block.stoneBrick.blockID);
		world.setBlock(i + 6, j + 2, k + 8, 0);
		world.setBlock(i + 6, j + 2, k + 9, 0);
		world.setBlock(i + 6, j + 2, k + 10, 0);
		world.setBlock(i + 6, j + 2, k + 11, Block.stoneBrick.blockID);
		world.setBlock(i + 6, j + 2, k + 12, Block.stoneBrick.blockID);
		world.setBlock(i + 6, j + 2, k + 13, 0);
		world.setBlock(i + 6, j + 2, k + 14, 0);
		world.setBlock(i + 6, j + 2, k + 15, 0);
		world.setBlock(i + 6, j + 2, k + 16, 0);
		world.setBlock(i + 6, j + 2, k + 17, 0);
		world.setBlock(i + 6, j + 2, k + 18, 0);
		world.setBlock(i + 6, j + 3, k + 0, 0);
		world.setBlock(i + 6, j + 3, k + 1, 0);
		world.setBlock(i + 6, j + 3, k + 2, 0);
		world.setBlock(i + 6, j + 3, k + 3, 0);
		world.setBlock(i + 6, j + 3, k + 4, 0);
		world.setBlock(i + 6, j + 3, k + 5, 0);
		world.setBlock(i + 6, j + 3, k + 6, Block.stoneBrick.blockID);
		world.setBlock(i + 6, j + 3, k + 7, Block.stoneBrick.blockID);
		world.setBlockAndMetadata(i + 6, j + 3, k + 8, Block.stoneSingleSlab.blockID, 13);
		world.setBlockAndMetadata(i + 6, j + 3, k + 9, Block.stoneSingleSlab.blockID, 13);
		world.setBlockAndMetadata(i + 6, j + 3, k + 10, Block.stoneSingleSlab.blockID, 13);
		world.setBlock(i + 6, j + 3, k + 11, Block.stoneBrick.blockID);
		world.setBlock(i + 6, j + 3, k + 12, Block.stoneBrick.blockID);
		world.setBlock(i + 6, j + 3, k + 13, 0);
		world.setBlock(i + 6, j + 3, k + 14, 0);
		world.setBlock(i + 6, j + 3, k + 15, 0);
		world.setBlock(i + 6, j + 3, k + 16, 0);
		world.setBlock(i + 6, j + 3, k + 17, 0);
		world.setBlock(i + 6, j + 3, k + 18, 0);
		world.setBlock(i + 6, j + 4, k + 0, 0);
		world.setBlock(i + 6, j + 4, k + 1, 0);
		world.setBlock(i + 6, j + 4, k + 2, 0);
		world.setBlock(i + 6, j + 4, k + 3, 0);
		world.setBlock(i + 6, j + 4, k + 4, 0);
		world.setBlock(i + 6, j + 4, k + 5, 0);
		world.setBlock(i + 6, j + 4, k + 6, Block.stoneBrick.blockID);
		world.setBlock(i + 6, j + 4, k + 7, Block.stoneBrick.blockID);
		world.setBlock(i + 6, j + 4, k + 8, Block.stoneBrick.blockID);
		world.setBlock(i + 6, j + 4, k + 9, Block.stoneBrick.blockID);
		world.setBlock(i + 6, j + 4, k + 10, Block.stoneBrick.blockID);
		world.setBlock(i + 6, j + 4, k + 11, Block.stoneBrick.blockID);
		world.setBlock(i + 6, j + 4, k + 12, Block.stoneBrick.blockID);
		world.setBlock(i + 6, j + 4, k + 13, 0);
		world.setBlock(i + 6, j + 4, k + 14, 0);
		world.setBlock(i + 6, j + 4, k + 15, 0);
		world.setBlock(i + 6, j + 4, k + 16, 0);
		world.setBlock(i + 6, j + 4, k + 17, 0);
		world.setBlock(i + 6, j + 4, k + 18, 0);
		world.setBlock(i + 6, j + 5, k + 0, 0);
		world.setBlock(i + 6, j + 5, k + 1, 0);
		world.setBlock(i + 6, j + 5, k + 2, 0);
		world.setBlock(i + 6, j + 5, k + 3, 0);
		world.setBlock(i + 6, j + 5, k + 4, 0);
		world.setBlock(i + 6, j + 5, k + 5, 0);
		world.setBlock(i + 6, j + 5, k + 6, Block.stoneBrick.blockID);
		world.setBlock(i + 6, j + 5, k + 7, Block.stoneBrick.blockID);
		world.setBlock(i + 6, j + 5, k + 8, Block.thinGlass.blockID);
		world.setBlock(i + 6, j + 5, k + 9, 0);
		world.setBlock(i + 6, j + 5, k + 10, Block.thinGlass.blockID);
		world.setBlock(i + 6, j + 5, k + 11, Block.stoneBrick.blockID);
		world.setBlock(i + 6, j + 5, k + 12, Block.stoneBrick.blockID);
		world.setBlock(i + 6, j + 5, k + 13, 0);
		world.setBlock(i + 6, j + 5, k + 14, 0);
		world.setBlock(i + 6, j + 5, k + 15, 0);
		world.setBlock(i + 6, j + 5, k + 16, 0);
		world.setBlock(i + 6, j + 5, k + 17, 0);
		world.setBlock(i + 6, j + 5, k + 18, 0);
		world.setBlock(i + 6, j + 6, k + 0, 0);
		world.setBlock(i + 6, j + 6, k + 1, 0);
		world.setBlock(i + 6, j + 6, k + 2, 0);
		world.setBlock(i + 6, j + 6, k + 3, 0);
		world.setBlock(i + 6, j + 6, k + 4, 0);
		world.setBlock(i + 6, j + 6, k + 5, 0);
		world.setBlock(i + 6, j + 6, k + 6, Block.stoneBrick.blockID);
		world.setBlock(i + 6, j + 6, k + 7, Block.stoneBrick.blockID);
		world.setBlock(i + 6, j + 6, k + 8, Block.thinGlass.blockID);
		world.setBlock(i + 6, j + 6, k + 9, 0);
		world.setBlock(i + 6, j + 6, k + 10, Block.thinGlass.blockID);
		world.setBlock(i + 6, j + 6, k + 11, Block.stoneBrick.blockID);
		world.setBlock(i + 6, j + 6, k + 12, Block.stoneBrick.blockID);
		world.setBlock(i + 6, j + 6, k + 13, 0);
		world.setBlock(i + 6, j + 6, k + 14, 0);
		world.setBlock(i + 6, j + 6, k + 15, 0);
		world.setBlock(i + 6, j + 6, k + 16, 0);
		world.setBlock(i + 6, j + 6, k + 17, 0);
		world.setBlock(i + 6, j + 6, k + 18, 0);
		world.setBlock(i + 6, j + 7, k + 0, 0);
		world.setBlock(i + 6, j + 7, k + 1, 0);
		world.setBlock(i + 6, j + 7, k + 2, 0);
		world.setBlock(i + 6, j + 7, k + 3, 0);
		world.setBlock(i + 6, j + 7, k + 4, 0);
		world.setBlock(i + 6, j + 7, k + 5, 0);
		world.setBlockAndMetadata(i + 6, j + 7, k + 6, Block.stairsStoneBrickSmooth.blockID, 2);
		world.setBlock(i + 6, j + 7, k + 7, Block.stairsStoneBrickSmooth.blockID);
		world.setBlock(i + 6, j + 7, k + 8, Block.stairsStoneBrickSmooth.blockID);
		world.setBlock(i + 6, j + 7, k + 9, Block.stoneBrick.blockID);
		world.setBlock(i + 6, j + 7, k + 10, Block.stairsStoneBrickSmooth.blockID);
		world.setBlock(i + 6, j + 7, k + 11, Block.stairsStoneBrickSmooth.blockID);
		world.setBlockAndMetadata(i + 6, j + 7, k + 12, Block.stairsStoneBrickSmooth.blockID, 3);
		world.setBlock(i + 6, j + 7, k + 13, 0);
		world.setBlock(i + 6, j + 7, k + 14, 0);
		world.setBlock(i + 6, j + 7, k + 15, 0);
		world.setBlock(i + 6, j + 7, k + 16, 0);
		world.setBlock(i + 6, j + 7, k + 17, 0);
		world.setBlock(i + 6, j + 7, k + 18, 0);
		world.setBlock(i + 6, j + 8, k + 0, 0);
		world.setBlock(i + 6, j + 8, k + 1, 0);
		world.setBlock(i + 6, j + 8, k + 2, 0);
		world.setBlock(i + 6, j + 8, k + 3, 0);
		world.setBlock(i + 6, j + 8, k + 4, 0);
		world.setBlock(i + 6, j + 8, k + 5, 0);
		world.setBlock(i + 6, j + 8, k + 6, 0);
		world.setBlock(i + 6, j + 8, k + 7, 0);
		world.setBlock(i + 6, j + 8, k + 8, 0);
		world.setBlock(i + 6, j + 8, k + 9, 0);
		world.setBlock(i + 6, j + 8, k + 10, 0);
		world.setBlock(i + 6, j + 8, k + 11, 0);
		world.setBlock(i + 6, j + 8, k + 12, 0);
		world.setBlock(i + 6, j + 8, k + 13, 0);
		world.setBlock(i + 6, j + 8, k + 14, 0);
		world.setBlock(i + 6, j + 8, k + 15, 0);
		world.setBlock(i + 6, j + 8, k + 16, 0);
		world.setBlock(i + 6, j + 8, k + 17, 0);
		world.setBlock(i + 6, j + 8, k + 18, 0);
		world.setBlock(i + 7, j + 0, k + 0, 0);
		world.setBlock(i + 7, j + 0, k + 1, 0);
		world.setBlock(i + 7, j + 0, k + 2, 0);
		world.setBlock(i + 7, j + 0, k + 3, 0);
		world.setBlock(i + 7, j + 0, k + 4, 0);
		world.setBlock(i + 7, j + 0, k + 5, Block.grass.blockID);
		world.setBlock(i + 7, j + 0, k + 6, Block.dirt.blockID);
		world.setBlock(i + 7, j + 0, k + 7, Block.grass.blockID);
		world.setBlock(i + 7, j + 0, k + 8, Block.grass.blockID);
		world.setBlock(i + 7, j + 0, k + 9, Block.grass.blockID);
		world.setBlock(i + 7, j + 0, k + 10, Block.grass.blockID);
		world.setBlock(i + 7, j + 0, k + 11, Block.grass.blockID);
		world.setBlock(i + 7, j + 0, k + 12, Block.dirt.blockID);
		world.setBlock(i + 7, j + 0, k + 13, Block.grass.blockID);
		world.setBlock(i + 7, j + 0, k + 14, 0);
		world.setBlock(i + 7, j + 0, k + 15, 0);
		world.setBlock(i + 7, j + 0, k + 16, 0);
		world.setBlock(i + 7, j + 0, k + 17, 0);
		world.setBlock(i + 7, j + 0, k + 18, 0);
		world.setBlock(i + 7, j + 1, k + 0, 0);
		world.setBlock(i + 7, j + 1, k + 1, 0);
		world.setBlock(i + 7, j + 1, k + 2, 0);
		world.setBlock(i + 7, j + 1, k + 3, 0);
		world.setBlock(i + 7, j + 1, k + 4, 0);
		world.setBlock(i + 7, j + 1, k + 5, 0);
		world.setBlock(i + 7, j + 1, k + 6, Block.stoneBrick.blockID);
		world.setBlock(i + 7, j + 1, k + 8, 0);
		world.setBlock(i + 7, j + 1, k + 9, 0);
		world.setBlock(i + 7, j + 1, k + 10, 0);
		world.setBlock(i + 7, j + 1, k + 12, Block.stoneBrick.blockID);
		world.setBlock(i + 7, j + 1, k + 13, 0);
		world.setBlock(i + 7, j + 1, k + 14, 0);
		world.setBlock(i + 7, j + 1, k + 15, 0);
		world.setBlock(i + 7, j + 1, k + 16, 0);
		world.setBlock(i + 7, j + 1, k + 17, 0);
		world.setBlock(i + 7, j + 1, k + 18, 0);
		world.setBlock(i + 7, j + 2, k + 0, 0);
		world.setBlock(i + 7, j + 2, k + 1, 0);
		world.setBlock(i + 7, j + 2, k + 2, 0);
		world.setBlock(i + 7, j + 2, k + 3, 0);
		world.setBlock(i + 7, j + 2, k + 4, 0);
		world.setBlock(i + 7, j + 2, k + 5, 0);
		world.setBlock(i + 7, j + 2, k + 6, Block.stoneBrick.blockID);
		world.setBlock(i + 7, j + 2, k + 8, 0);
		world.setBlock(i + 7, j + 2, k + 9, 0);
		world.setBlock(i + 7, j + 2, k + 10, 0);
		world.setBlock(i + 7, j + 2, k + 12, Block.stoneBrick.blockID);
		world.setBlock(i + 7, j + 2, k + 13, 0);
		world.setBlock(i + 7, j + 2, k + 14, 0);
		world.setBlock(i + 7, j + 2, k + 15, 0);
		world.setBlock(i + 7, j + 2, k + 16, 0);
		world.setBlock(i + 7, j + 2, k + 17, 0);
		world.setBlock(i + 7, j + 2, k + 18, 0);
		world.setBlock(i + 7, j + 3, k + 0, 0);
		world.setBlock(i + 7, j + 3, k + 1, 0);
		world.setBlock(i + 7, j + 3, k + 2, 0);
		world.setBlock(i + 7, j + 3, k + 3, 0);
		world.setBlock(i + 7, j + 3, k + 4, 0);
		world.setBlock(i + 7, j + 3, k + 5, 0);
		world.setBlock(i + 7, j + 3, k + 6, Block.stoneBrick.blockID);
		world.setBlock(i + 7, j + 3, k + 8, 0);
		world.setBlock(i + 7, j + 3, k + 9, 0);
		world.setBlock(i + 7, j + 3, k + 10, 0);
		world.setBlock(i + 7, j + 3, k + 12, Block.stoneBrick.blockID);
		world.setBlock(i + 7, j + 3, k + 13, 0);
		world.setBlock(i + 7, j + 3, k + 14, 0);
		world.setBlock(i + 7, j + 3, k + 15, 0);
		world.setBlock(i + 7, j + 3, k + 16, 0);
		world.setBlock(i + 7, j + 3, k + 17, 0);
		world.setBlock(i + 7, j + 3, k + 18, 0);
		world.setBlock(i + 7, j + 4, k + 0, 0);
		world.setBlock(i + 7, j + 4, k + 1, 0);
		world.setBlock(i + 7, j + 4, k + 2, 0);
		world.setBlock(i + 7, j + 4, k + 3, 0);
		world.setBlock(i + 7, j + 4, k + 4, 0);
		world.setBlock(i + 7, j + 4, k + 5, 0);
		world.setBlock(i + 7, j + 4, k + 6, Block.stoneBrick.blockID);
		world.setBlock(i + 7, j + 4, k + 8, Block.stoneBrick.blockID);
		world.setBlock(i + 7, j + 4, k + 9, Block.stoneBrick.blockID);
		world.setBlock(i + 7, j + 4, k + 10, Block.stoneBrick.blockID);
		world.setBlock(i + 7, j + 4, k + 12, Block.stoneBrick.blockID);
		world.setBlock(i + 7, j + 4, k + 13, 0);
		world.setBlock(i + 7, j + 4, k + 14, 0);
		world.setBlock(i + 7, j + 4, k + 15, 0);
		world.setBlock(i + 7, j + 4, k + 16, 0);
		world.setBlock(i + 7, j + 4, k + 17, 0);
		world.setBlock(i + 7, j + 4, k + 18, 0);
		world.setBlock(i + 7, j + 5, k + 0, 0);
		world.setBlock(i + 7, j + 5, k + 1, 0);
		world.setBlock(i + 7, j + 5, k + 2, 0);
		world.setBlock(i + 7, j + 5, k + 3, 0);
		world.setBlock(i + 7, j + 5, k + 4, 0);
		world.setBlock(i + 7, j + 5, k + 5, 0);
		world.setBlock(i + 7, j + 5, k + 6, Block.stoneBrick.blockID);
		world.setBlock(i + 7, j + 5, k + 8, 0);
		world.setBlock(i + 7, j + 5, k + 9, 0);
		world.setBlock(i + 7, j + 5, k + 10, 0);
		world.setBlock(i + 7, j + 5, k + 12, Block.stoneBrick.blockID);
		world.setBlock(i + 7, j + 5, k + 13, 0);
		world.setBlock(i + 7, j + 5, k + 14, 0);
		world.setBlock(i + 7, j + 5, k + 15, 0);
		world.setBlock(i + 7, j + 5, k + 16, 0);
		world.setBlock(i + 7, j + 5, k + 17, 0);
		world.setBlock(i + 7, j + 5, k + 18, 0);
		world.setBlock(i + 7, j + 6, k + 0, 0);
		world.setBlock(i + 7, j + 6, k + 1, 0);
		world.setBlock(i + 7, j + 6, k + 2, 0);
		world.setBlock(i + 7, j + 6, k + 3, 0);
		world.setBlock(i + 7, j + 6, k + 4, 0);
		world.setBlock(i + 7, j + 6, k + 5, 0);
		world.setBlock(i + 7, j + 6, k + 6, Block.stoneBrick.blockID);
		world.setBlock(i + 7, j + 6, k + 8, 0);
		world.setBlock(i + 7, j + 6, k + 9, 0);
		world.setBlock(i + 7, j + 6, k + 10, 0);
		world.setBlock(i + 7, j + 6, k + 12, Block.stoneBrick.blockID);
		world.setBlock(i + 7, j + 6, k + 13, 0);
		world.setBlock(i + 7, j + 6, k + 14, 0);
		world.setBlock(i + 7, j + 6, k + 15, 0);
		world.setBlock(i + 7, j + 6, k + 16, 0);
		world.setBlock(i + 7, j + 6, k + 17, 0);
		world.setBlock(i + 7, j + 6, k + 18, 0);
		world.setBlock(i + 7, j + 7, k + 0, 0);
		world.setBlock(i + 7, j + 7, k + 1, 0);
		world.setBlock(i + 7, j + 7, k + 2, 0);
		world.setBlock(i + 7, j + 7, k + 3, 0);
		world.setBlock(i + 7, j + 7, k + 4, 0);
		world.setBlock(i + 7, j + 7, k + 5, 0);
		world.setBlockAndMetadata(i + 7, j + 7, k + 6, Block.stairsStoneBrickSmooth.blockID, 2);
		world.setBlock(i + 7, j + 7, k + 7, 0);
		world.setBlock(i + 7, j + 7, k + 8, 0);
		world.setBlock(i + 7, j + 7, k + 9, 0);
		world.setBlock(i + 7, j + 7, k + 10, 0);
		world.setBlock(i + 7, j + 7, k + 11, 0);
		world.setBlockAndMetadata(i + 7, j + 7, k + 12, Block.stairsStoneBrickSmooth.blockID, 3);
		world.setBlock(i + 7, j + 7, k + 13, 0);
		world.setBlock(i + 7, j + 7, k + 14, 0);
		world.setBlock(i + 7, j + 7, k + 15, 0);
		world.setBlock(i + 7, j + 7, k + 16, 0);
		world.setBlock(i + 7, j + 7, k + 17, 0);
		world.setBlock(i + 7, j + 7, k + 18, 0);
		world.setBlock(i + 7, j + 8, k + 0, 0);
		world.setBlock(i + 7, j + 8, k + 1, 0);
		world.setBlock(i + 7, j + 8, k + 2, 0);
		world.setBlock(i + 7, j + 8, k + 3, 0);
		world.setBlock(i + 7, j + 8, k + 4, 0);
		world.setBlock(i + 7, j + 8, k + 5, 0);
		world.setBlock(i + 7, j + 8, k + 6, 0);
		world.setBlock(i + 7, j + 8, k + 7, Block.stairsStoneBrickSmooth.blockID);
		world.setBlock(i + 7, j + 8, k + 8, Block.stairsStoneBrickSmooth.blockID);
		world.setBlock(i + 7, j + 8, k + 9, Block.stairsStoneBrickSmooth.blockID);
		world.setBlock(i + 7, j + 8, k + 10, Block.stairsStoneBrickSmooth.blockID);
		world.setBlock(i + 7, j + 8, k + 11, Block.stairsStoneBrickSmooth.blockID);
		world.setBlock(i + 7, j + 8, k + 12, 0);
		world.setBlock(i + 7, j + 8, k + 13, 0);
		world.setBlock(i + 7, j + 8, k + 14, 0);
		world.setBlock(i + 7, j + 8, k + 15, 0);
		world.setBlock(i + 7, j + 8, k + 16, 0);
		world.setBlock(i + 7, j + 8, k + 17, 0);
		world.setBlock(i + 7, j + 8, k + 18, 0);
		world.setBlock(i + 8, j + 0, k + 0, 0);
		world.setBlock(i + 8, j + 0, k + 1, 0);
		world.setBlock(i + 8, j + 0, k + 2, 0);
		world.setBlock(i + 8, j + 0, k + 3, 0);
		world.setBlock(i + 8, j + 0, k + 4, 0);
		world.setBlock(i + 8, j + 0, k + 5, Block.grass.blockID);
		world.setBlock(i + 8, j + 0, k + 6, Block.stone.blockID);
		world.setBlock(i + 8, j + 0, k + 7, Block.grass.blockID);
		world.setBlock(i + 8, j + 0, k + 8, Block.stone.blockID);
		world.setBlock(i + 8, j + 0, k + 9, Block.grass.blockID);
		world.setBlock(i + 8, j + 0, k + 10, Block.stone.blockID);
		world.setBlock(i + 8, j + 0, k + 11, Block.grass.blockID);
		world.setBlock(i + 8, j + 0, k + 12, Block.stone.blockID);
		world.setBlock(i + 8, j + 0, k + 13, Block.grass.blockID);
		world.setBlock(i + 8, j + 0, k + 14, 0);
		world.setBlock(i + 8, j + 0, k + 15, 0);
		world.setBlock(i + 8, j + 0, k + 16, 0);
		world.setBlock(i + 8, j + 0, k + 17, 0);
		world.setBlock(i + 8, j + 0, k + 18, 0);
		world.setBlock(i + 8, j + 1, k + 0, 0);
		world.setBlock(i + 8, j + 1, k + 1, 0);
		world.setBlock(i + 8, j + 1, k + 2, 0);
		world.setBlock(i + 8, j + 1, k + 3, 0);
		world.setBlock(i + 8, j + 1, k + 4, 0);
		world.setBlock(i + 8, j + 1, k + 5, 0);
		world.setBlock(i + 8, j + 1, k + 6, 0);
		world.setBlock(i + 8, j + 1, k + 7, 0);
		world.setBlock(i + 8, j + 1, k + 8, 0);
		world.setBlock(i + 8, j + 1, k + 9, 0);
		world.setBlock(i + 8, j + 1, k + 10, 0);
		world.setBlock(i + 8, j + 1, k + 11, 0);
		world.setBlock(i + 8, j + 1, k + 12, 0);
		world.setBlock(i + 8, j + 1, k + 13, 0);
		world.setBlock(i + 8, j + 1, k + 14, 0);
		world.setBlock(i + 8, j + 1, k + 15, 0);
		world.setBlock(i + 8, j + 1, k + 16, 0);
		world.setBlock(i + 8, j + 1, k + 17, 0);
		world.setBlock(i + 8, j + 1, k + 18, 0);
		world.setBlock(i + 8, j + 2, k + 0, 0);
		world.setBlock(i + 8, j + 2, k + 1, 0);
		world.setBlock(i + 8, j + 2, k + 2, 0);
		world.setBlock(i + 8, j + 2, k + 3, 0);
		world.setBlock(i + 8, j + 2, k + 4, 0);
		world.setBlock(i + 8, j + 2, k + 5, 0);
		world.setBlock(i + 8, j + 2, k + 6, 0);
		world.setBlock(i + 8, j + 2, k + 7, 0);
		world.setBlock(i + 8, j + 2, k + 8, 0);
		world.setBlock(i + 8, j + 2, k + 9, 0);
		world.setBlock(i + 8, j + 2, k + 10, 0);
		world.setBlock(i + 8, j + 2, k + 11, 0);
		world.setBlock(i + 8, j + 2, k + 12, 0);
		world.setBlock(i + 8, j + 2, k + 13, 0);
		world.setBlock(i + 8, j + 2, k + 14, 0);
		world.setBlock(i + 8, j + 2, k + 15, 0);
		world.setBlock(i + 8, j + 2, k + 16, 0);
		world.setBlock(i + 8, j + 2, k + 17, 0);
		world.setBlock(i + 8, j + 2, k + 18, 0);
		world.setBlock(i + 8, j + 3, k + 0, 0);
		world.setBlock(i + 8, j + 3, k + 1, 0);
		world.setBlock(i + 8, j + 3, k + 2, 0);
		world.setBlock(i + 8, j + 3, k + 3, 0);
		world.setBlock(i + 8, j + 3, k + 4, 0);
		world.setBlock(i + 8, j + 3, k + 5, 0);
		world.setBlockAndMetadata(i + 8, j + 3, k + 6, Block.stoneSingleSlab.blockID, 13);
		world.setBlock(i + 8, j + 3, k + 7, 0);
		world.setBlock(i + 8, j + 3, k + 8, 0);
		world.setBlock(i + 8, j + 3, k + 9, 0);
		world.setBlock(i + 8, j + 3, k + 10, 0);
		world.setBlock(i + 8, j + 3, k + 11, 0);
		world.setBlockAndMetadata(i + 8, j + 3, k + 12, Block.stoneSingleSlab.blockID, 13);
		world.setBlock(i + 8, j + 3, k + 13, 0);
		world.setBlock(i + 8, j + 3, k + 14, 0);
		world.setBlock(i + 8, j + 3, k + 15, 0);
		world.setBlock(i + 8, j + 3, k + 16, 0);
		world.setBlock(i + 8, j + 3, k + 17, 0);
		world.setBlock(i + 8, j + 3, k + 18, 0);
		world.setBlock(i + 8, j + 4, k + 0, 0);
		world.setBlock(i + 8, j + 4, k + 1, Block.stoneBrick.blockID);
		world.setBlock(i + 8, j + 4, k + 2, Block.stoneBrick.blockID);
		world.setBlock(i + 8, j + 4, k + 3, Block.stoneBrick.blockID);
		world.setBlock(i + 8, j + 4, k + 4, Block.stoneBrick.blockID);
		world.setBlock(i + 8, j + 4, k + 5, Block.stoneBrick.blockID);
		world.setBlock(i + 8, j + 4, k + 6, Block.stoneBrick.blockID);
		world.setBlock(i + 8, j + 4, k + 7, Block.stoneBrick.blockID);
		world.setBlock(i + 8, j + 4, k + 8, Block.stoneBrick.blockID);
		world.setBlock(i + 8, j + 4, k + 9, Block.stoneBrick.blockID);
		world.setBlock(i + 8, j + 4, k + 10, Block.stoneBrick.blockID);
		world.setBlock(i + 8, j + 4, k + 11, Block.stoneBrick.blockID);
		world.setBlock(i + 8, j + 4, k + 12, Block.stoneBrick.blockID);
		world.setBlock(i + 8, j + 4, k + 13, Block.stoneBrick.blockID);
		world.setBlock(i + 8, j + 4, k + 14, Block.stoneBrick.blockID);
		world.setBlock(i + 8, j + 4, k + 15, Block.stoneBrick.blockID);
		world.setBlock(i + 8, j + 4, k + 16, Block.stoneBrick.blockID);
		world.setBlock(i + 8, j + 4, k + 17, Block.stoneBrick.blockID);
		world.setBlock(i + 8, j + 4, k + 18, 0);
		world.setBlock(i + 8, j + 5, k + 0, 0);
		world.setBlock(i + 8, j + 5, k + 1, Block.thinGlass.blockID);
		world.setBlock(i + 8, j + 5, k + 2, Block.thinGlass.blockID);
		world.setBlock(i + 8, j + 5, k + 3, Block.thinGlass.blockID);
		world.setBlock(i + 8, j + 5, k + 4, Block.thinGlass.blockID);
		world.setBlock(i + 8, j + 5, k + 5, Block.thinGlass.blockID);
		world.setBlock(i + 8, j + 5, k + 6, Block.thinGlass.blockID);
		world.setBlock(i + 8, j + 5, k + 7, 0);
		world.setBlock(i + 8, j + 5, k + 8, 0);
		world.setBlock(i + 8, j + 5, k + 9, 0);
		world.setBlock(i + 8, j + 5, k + 10, 0);
		world.setBlock(i + 8, j + 5, k + 11, 0);
		world.setBlock(i + 8, j + 5, k + 12, Block.thinGlass.blockID);
		world.setBlock(i + 8, j + 5, k + 13, Block.thinGlass.blockID);
		world.setBlock(i + 8, j + 5, k + 14, Block.thinGlass.blockID);
		world.setBlock(i + 8, j + 5, k + 15, Block.thinGlass.blockID);
		world.setBlock(i + 8, j + 5, k + 16, Block.thinGlass.blockID);
		world.setBlock(i + 8, j + 5, k + 17, Block.thinGlass.blockID);
		world.setBlock(i + 8, j + 5, k + 18, 0);
		world.setBlock(i + 8, j + 6, k + 0, 0);
		world.setBlock(i + 8, j + 6, k + 1, Block.thinGlass.blockID);
		world.setBlock(i + 8, j + 6, k + 2, Block.thinGlass.blockID);
		world.setBlock(i + 8, j + 6, k + 3, Block.thinGlass.blockID);
		world.setBlock(i + 8, j + 6, k + 4, Block.thinGlass.blockID);
		world.setBlock(i + 8, j + 6, k + 5, Block.thinGlass.blockID);
		world.setBlock(i + 8, j + 6, k + 6, Block.thinGlass.blockID);
		world.setBlock(i + 8, j + 6, k + 7, 0);
		world.setBlock(i + 8, j + 6, k + 8, 0);
		world.setBlock(i + 8, j + 6, k + 9, 0);
		world.setBlock(i + 8, j + 6, k + 10, 0);
		world.setBlock(i + 8, j + 6, k + 11, 0);
		world.setBlock(i + 8, j + 6, k + 12, Block.thinGlass.blockID);
		world.setBlock(i + 8, j + 6, k + 13, Block.thinGlass.blockID);
		world.setBlock(i + 8, j + 6, k + 14, Block.thinGlass.blockID);
		world.setBlock(i + 8, j + 6, k + 15, Block.thinGlass.blockID);
		world.setBlock(i + 8, j + 6, k + 16, Block.thinGlass.blockID);
		world.setBlock(i + 8, j + 6, k + 17, Block.thinGlass.blockID);
		world.setBlock(i + 8, j + 6, k + 18, 0);
		world.setBlockAndMetadata(i + 8, j + 7, k + 0, Block.stairsStoneBrickSmooth.blockID, 2);
		world.setBlock(i + 8, j + 7, k + 1, Block.stairsStoneBrickSmooth.blockID);
		world.setBlock(i + 8, j + 7, k + 2, Block.stairsStoneBrickSmooth.blockID);
		world.setBlock(i + 8, j + 7, k + 3, Block.stairsStoneBrickSmooth.blockID);
		world.setBlock(i + 8, j + 7, k + 4, Block.stairsStoneBrickSmooth.blockID);
		world.setBlock(i + 8, j + 7, k + 5, Block.stairsStoneBrickSmooth.blockID);
		world.setBlockAndMetadata(i + 8, j + 7, k + 6, Block.stairsStoneBrickSmooth.blockID, 2);
		world.setBlock(i + 8, j + 7, k + 7, 0);
		world.setBlock(i + 8, j + 7, k + 8, 0);
		world.setBlock(i + 8, j + 7, k + 9, 0);
		world.setBlock(i + 8, j + 7, k + 10, 0);
		world.setBlock(i + 8, j + 7, k + 11, 0);
		world.setBlockAndMetadata(i + 8, j + 7, k + 12, Block.stairsStoneBrickSmooth.blockID, 3);
		world.setBlock(i + 8, j + 7, k + 13, Block.stairsStoneBrickSmooth.blockID);
		world.setBlock(i + 8, j + 7, k + 14, Block.stairsStoneBrickSmooth.blockID);
		world.setBlock(i + 8, j + 7, k + 15, Block.stairsStoneBrickSmooth.blockID);
		world.setBlock(i + 8, j + 7, k + 16, Block.stairsStoneBrickSmooth.blockID);
		world.setBlock(i + 8, j + 7, k + 17, Block.stairsStoneBrickSmooth.blockID);
		world.setBlock(i + 8, j + 7, k + 18, Block.stairsStoneBrickSmooth.blockID);
	}

	public void generate2() 
	{
		world.setBlock(i + 8, j + 8, k + 0, 0);
		world.setBlock(i + 8, j + 8, k + 1, 0);
		world.setBlock(i + 8, j + 8, k + 2, 0);
		world.setBlock(i + 8, j + 8, k + 3, 0);
		world.setBlock(i + 8, j + 8, k + 4, 0);
		world.setBlock(i + 8, j + 8, k + 5, 0);
		world.setBlock(i + 8, j + 8, k + 6, 0);
		world.setBlockAndMetadata(i + 8, j + 8, k + 7, Block.stairsStoneBrickSmooth.blockID, 2);
		world.setBlock(i + 8, j + 8, k + 8, Block.stoneBrick.blockID);
		world.setBlock(i + 8, j + 8, k + 9, Block.stoneBrick.blockID);
		world.setBlock(i + 8, j + 8, k + 10, Block.stoneBrick.blockID);
		world.setBlockAndMetadata(i + 8, j + 8, k + 11, Block.stairsStoneBrickSmooth.blockID, 3);
		world.setBlock(i + 8, j + 8, k + 12, 0);
		world.setBlock(i + 8, j + 8, k + 13, 0);
		world.setBlock(i + 8, j + 8, k + 14, 0);
		world.setBlock(i + 8, j + 8, k + 15, 0);
		world.setBlock(i + 8, j + 8, k + 16, 0);
		world.setBlock(i + 8, j + 8, k + 17, 0);
		world.setBlock(i + 8, j + 8, k + 18, 0);
		world.setBlock(i + 9, j + 0, k + 0, 0);
		world.setBlock(i + 9, j + 0, k + 1, 0);
		world.setBlock(i + 9, j + 0, k + 2, 0);
		world.setBlock(i + 9, j + 0, k + 3, 0);
		world.setBlock(i + 9, j + 0, k + 4, 0);
		world.setBlock(i + 9, j + 0, k + 5, Block.grass.blockID);
		world.setBlock(i + 9, j + 0, k + 6, Block.grass.blockID);
		world.setBlock(i + 9, j + 0, k + 7, Block.grass.blockID);
		world.setBlock(i + 9, j + 0, k + 8, Block.grass.blockID);
		world.setBlock(i + 9, j + 0, k + 9, Block.grass.blockID);
		world.setBlock(i + 9, j + 0, k + 10, Block.grass.blockID);
		world.setBlock(i + 9, j + 0, k + 11, Block.grass.blockID);
		world.setBlock(i + 9, j + 0, k + 12, Block.grass.blockID);
		world.setBlock(i + 9, j + 0, k + 13, Block.grass.blockID);
		world.setBlock(i + 9, j + 0, k + 14, 0);
		world.setBlock(i + 9, j + 0, k + 15, 0);
		world.setBlock(i + 9, j + 0, k + 16, 0);
		world.setBlock(i + 9, j + 0, k + 17, 0);
		world.setBlock(i + 9, j + 0, k + 18, 0);
		world.setBlock(i + 9, j + 1, k + 0, 0);
		world.setBlock(i + 9, j + 1, k + 1, 0);
		world.setBlock(i + 9, j + 1, k + 2, 0);
		world.setBlock(i + 9, j + 1, k + 3, 0);
		world.setBlock(i + 9, j + 1, k + 4, 0);
		world.setBlock(i + 9, j + 1, k + 5, 0);
		world.setBlock(i + 9, j + 1, k + 6, 0);
		world.setBlock(i + 9, j + 1, k + 7, 0);
		world.setBlock(i + 9, j + 1, k + 8, 0);
		//world.setBlock(i + 9, j + 1, k + 9, 0);
		world.setBlock(i + 9, j + 1, k + 10, 0);
		world.setBlock(i + 9, j + 1, k + 11, 0);
		world.setBlock(i + 9, j + 1, k + 12, 0);
		world.setBlock(i + 9, j + 1, k + 13, 0);
		world.setBlock(i + 9, j + 1, k + 14, 0);
		world.setBlock(i + 9, j + 1, k + 15, 0);
		world.setBlock(i + 9, j + 1, k + 16, 0);
		world.setBlock(i + 9, j + 1, k + 17, 0);
		world.setBlock(i + 9, j + 1, k + 18, 0);
		world.setBlock(i + 9, j + 2, k + 0, 0);
		world.setBlock(i + 9, j + 2, k + 1, 0);
		world.setBlock(i + 9, j + 2, k + 2, 0);
		world.setBlock(i + 9, j + 2, k + 3, 0);
		world.setBlock(i + 9, j + 2, k + 4, 0);
		world.setBlock(i + 9, j + 2, k + 5, 0);
		world.setBlock(i + 9, j + 2, k + 6, 0);
		world.setBlock(i + 9, j + 2, k + 7, 0);
		world.setBlock(i + 9, j + 2, k + 8, 0);
		world.setBlock(i + 9, j + 2, k + 9, 0);
		world.setBlock(i + 9, j + 2, k + 10, 0);
		world.setBlock(i + 9, j + 2, k + 11, 0);
		world.setBlock(i + 9, j + 2, k + 12, 0);
		world.setBlock(i + 9, j + 2, k + 13, 0);
		world.setBlock(i + 9, j + 2, k + 14, 0);
		world.setBlock(i + 9, j + 2, k + 15, 0);
		world.setBlock(i + 9, j + 2, k + 16, 0);
		world.setBlock(i + 9, j + 2, k + 17, 0);
		world.setBlock(i + 9, j + 2, k + 18, 0);
		world.setBlock(i + 9, j + 3, k + 0, 0);
		world.setBlock(i + 9, j + 3, k + 1, 0);
		world.setBlock(i + 9, j + 3, k + 2, 0);
		world.setBlock(i + 9, j + 3, k + 3, 0);
		world.setBlock(i + 9, j + 3, k + 4, 0);
		world.setBlock(i + 9, j + 3, k + 5, 0);
		world.setBlockAndMetadata(i + 9, j + 3, k + 6, Block.stoneSingleSlab.blockID, 13);
		world.setBlock(i + 9, j + 3, k + 7, 0);
		world.setBlock(i + 9, j + 3, k + 8, 0);
		world.setBlock(i + 9, j + 3, k + 9, 0);
		world.setBlock(i + 9, j + 3, k + 10, 0);
		world.setBlock(i + 9, j + 3, k + 11, 0);
		world.setBlockAndMetadata(i + 9, j + 3, k + 12, Block.stoneSingleSlab.blockID, 13);
		world.setBlock(i + 9, j + 3, k + 13, 0);
		world.setBlock(i + 9, j + 3, k + 14, 0);
		world.setBlock(i + 9, j + 3, k + 15, 0);
		world.setBlock(i + 9, j + 3, k + 16, 0);
		world.setBlock(i + 9, j + 3, k + 17, 0);
		world.setBlock(i + 9, j + 3, k + 18, 0);
		world.setBlock(i + 9, j + 4, k + 0, 0);
		world.setBlock(i + 9, j + 4, k + 1, Block.stoneBrick.blockID);
		world.setBlock(i + 9, j + 4, k + 2, Block.stoneBrick.blockID);
		world.setBlock(i + 9, j + 4, k + 3, Block.stoneBrick.blockID);
		world.setBlock(i + 9, j + 4, k + 4, Block.stoneBrick.blockID);
		world.setBlock(i + 9, j + 4, k + 5, Block.stoneBrick.blockID);
		world.setBlock(i + 9, j + 4, k + 6, Block.stoneBrick.blockID);
		world.setBlock(i + 9, j + 4, k + 7, Block.stoneBrick.blockID);
		world.setBlock(i + 9, j + 4, k + 8, Block.stoneBrick.blockID);
		world.setBlock(i + 9, j + 4, k + 9, Block.glowStone.blockID);
		world.setBlock(i + 9, j + 4, k + 10, Block.stoneBrick.blockID);
		world.setBlock(i + 9, j + 4, k + 11, Block.stoneBrick.blockID);
		world.setBlock(i + 9, j + 4, k + 12, Block.stoneBrick.blockID);
		world.setBlock(i + 9, j + 4, k + 13, Block.stoneBrick.blockID);
		world.setBlock(i + 9, j + 4, k + 14, Block.stoneBrick.blockID);
		world.setBlock(i + 9, j + 4, k + 15, Block.stoneBrick.blockID);
		world.setBlock(i + 9, j + 4, k + 16, Block.stoneBrick.blockID);
		world.setBlock(i + 9, j + 4, k + 17, Block.stoneBrick.blockID);
		world.setBlock(i + 9, j + 4, k + 18, 0);
		world.setBlock(i + 9, j + 5, k + 0, 0);
		world.setBlock(i + 9, j + 5, k + 1, 0);
		world.setBlock(i + 9, j + 5, k + 2, 0);
		world.setBlock(i + 9, j + 5, k + 3, 0);
		world.setBlock(i + 9, j + 5, k + 4, 0);
		world.setBlock(i + 9, j + 5, k + 5, 0);
		world.setBlock(i + 9, j + 5, k + 6, 0);
		world.setBlock(i + 9, j + 5, k + 7, 0);
		world.setBlock(i + 9, j + 5, k + 8, 0);
		world.setBlock(i + 9, j + 5, k + 9, 0);
		world.setBlock(i + 9, j + 5, k + 10, 0);
		world.setBlock(i + 9, j + 5, k + 11, 0);
		world.setBlock(i + 9, j + 5, k + 12, 0);
		world.setBlock(i + 9, j + 5, k + 13, 0);
		world.setBlock(i + 9, j + 5, k + 14, 0);
		world.setBlock(i + 9, j + 5, k + 15, 0);
		world.setBlock(i + 9, j + 5, k + 16, 0);
		world.setBlock(i + 9, j + 5, k + 17, 0);
		world.setBlock(i + 9, j + 5, k + 18, 0);
		world.setBlock(i + 9, j + 6, k + 0, 0);
		world.setBlock(i + 9, j + 6, k + 1, 0);
		world.setBlock(i + 9, j + 6, k + 2, 0);
		world.setBlock(i + 9, j + 6, k + 3, 0);
		world.setBlock(i + 9, j + 6, k + 4, 0);
		world.setBlock(i + 9, j + 6, k + 5, 0);
		world.setBlock(i + 9, j + 6, k + 6, 0);
		world.setBlock(i + 9, j + 6, k + 7, 0);
		world.setBlock(i + 9, j + 6, k + 8, 0);
		world.setBlock(i + 9, j + 6, k + 9, 0);
		world.setBlock(i + 9, j + 6, k + 10, 0);
		world.setBlock(i + 9, j + 6, k + 11, 0);
		world.setBlock(i + 9, j + 6, k + 12, 0);
		world.setBlock(i + 9, j + 6, k + 13, 0);
		world.setBlock(i + 9, j + 6, k + 14, 0);
		world.setBlock(i + 9, j + 6, k + 15, 0);
		world.setBlock(i + 9, j + 6, k + 16, 0);
		world.setBlock(i + 9, j + 6, k + 17, 0);
		world.setBlock(i + 9, j + 6, k + 18, 0);
		world.setBlockAndMetadata(i + 9, j + 7, k + 0, Block.stairsStoneBrickSmooth.blockID, 2);
		world.setBlock(i + 9, j + 7, k + 1, Block.stoneBrick.blockID);
		world.setBlock(i + 9, j + 7, k + 2, Block.stoneBrick.blockID);
		world.setBlock(i + 9, j + 7, k + 3, Block.stoneBrick.blockID);
		world.setBlock(i + 9, j + 7, k + 4, Block.stoneBrick.blockID);
		world.setBlock(i + 9, j + 7, k + 5, Block.stoneBrick.blockID);
		world.setBlock(i + 9, j + 7, k + 6, Block.stoneBrick.blockID);
		world.setBlock(i + 9, j + 7, k + 7, 0);
		world.setBlock(i + 9, j + 7, k + 8, 0);
		world.setBlock(i + 9, j + 7, k + 9, 0);
		world.setBlock(i + 9, j + 7, k + 10, 0);
		world.setBlock(i + 9, j + 7, k + 11, 0);
		world.setBlock(i + 9, j + 7, k + 12, Block.stoneBrick.blockID);
		world.setBlock(i + 9, j + 7, k + 13, Block.stoneBrick.blockID);
		world.setBlock(i + 9, j + 7, k + 14, Block.stoneBrick.blockID);
		world.setBlock(i + 9, j + 7, k + 15, Block.stoneBrick.blockID);
		world.setBlock(i + 9, j + 7, k + 16, Block.stoneBrick.blockID);
		world.setBlock(i + 9, j + 7, k + 17, Block.stoneBrick.blockID);
		world.setBlockAndMetadata(i + 9, j + 7, k + 18, Block.stairsStoneBrickSmooth.blockID, 3);
		world.setBlock(i + 9, j + 8, k + 0, 0);
		world.setBlock(i + 9, j + 8, k + 1, 0);
		world.setBlock(i + 9, j + 8, k + 2, 0);
		world.setBlock(i + 9, j + 8, k + 3, 0);
		world.setBlock(i + 9, j + 8, k + 4, 0);
		world.setBlock(i + 9, j + 8, k + 5, 0);
		world.setBlock(i + 9, j + 8, k + 6, 0);
		world.setBlockAndMetadata(i + 9, j + 8, k + 7, Block.stairsStoneBrickSmooth.blockID, 2);
		world.setBlock(i + 9, j + 8, k + 8, Block.stoneBrick.blockID);
		world.setBlock(i + 9, j + 8, k + 9, Block.glowStone.blockID);
		world.setBlock(i + 9, j + 8, k + 10, Block.stoneBrick.blockID);
		world.setBlockAndMetadata(i + 9, j + 8, k + 11, Block.stairsStoneBrickSmooth.blockID, 3);
		world.setBlock(i + 9, j + 8, k + 12, 0);
		world.setBlock(i + 9, j + 8, k + 13, 0);
		world.setBlock(i + 9, j + 8, k + 14, 0);
		world.setBlock(i + 9, j + 8, k + 15, 0);
		world.setBlock(i + 9, j + 8, k + 16, 0);
		world.setBlock(i + 9, j + 8, k + 17, 0);
		world.setBlock(i + 9, j + 8, k + 18, 0);
		world.setBlock(i + 10, j + 0, k + 0, 0);
		world.setBlock(i + 10, j + 0, k + 1, 0);
		world.setBlock(i + 10, j + 0, k + 2, 0);
		world.setBlock(i + 10, j + 0, k + 3, 0);
		world.setBlock(i + 10, j + 0, k + 4, 0);
		world.setBlock(i + 10, j + 0, k + 5, Block.grass.blockID);
		world.setBlock(i + 10, j + 0, k + 6, Block.stone.blockID);
		world.setBlock(i + 10, j + 0, k + 7, Block.grass.blockID);
		world.setBlock(i + 10, j + 0, k + 8, Block.stone.blockID);
		world.setBlock(i + 10, j + 0, k + 9, Block.grass.blockID);
		world.setBlock(i + 10, j + 0, k + 10, Block.stone.blockID);
		world.setBlock(i + 10, j + 0, k + 11, Block.grass.blockID);
		world.setBlock(i + 10, j + 0, k + 12, Block.stone.blockID);
		world.setBlock(i + 10, j + 0, k + 13, Block.grass.blockID);
		world.setBlock(i + 10, j + 0, k + 14, 0);
		world.setBlock(i + 10, j + 0, k + 15, 0);
		world.setBlock(i + 10, j + 0, k + 16, 0);
		world.setBlock(i + 10, j + 0, k + 17, 0);
		world.setBlock(i + 10, j + 0, k + 18, 0);
		world.setBlock(i + 10, j + 1, k + 0, 0);
		world.setBlock(i + 10, j + 1, k + 1, 0);
		world.setBlock(i + 10, j + 1, k + 2, 0);
		world.setBlock(i + 10, j + 1, k + 3, 0);
		world.setBlock(i + 10, j + 1, k + 4, 0);
		world.setBlock(i + 10, j + 1, k + 5, 0);
		world.setBlock(i + 10, j + 1, k + 6, 0);
		world.setBlock(i + 10, j + 1, k + 7, 0);
		world.setBlock(i + 10, j + 1, k + 8, 0);
		world.setBlock(i + 10, j + 1, k + 9, 0);
		world.setBlock(i + 10, j + 1, k + 10, 0);
		world.setBlock(i + 10, j + 1, k + 11, 0);
		world.setBlock(i + 10, j + 1, k + 12, 0);
		world.setBlock(i + 10, j + 1, k + 13, 0);
		world.setBlock(i + 10, j + 1, k + 14, 0);
		world.setBlock(i + 10, j + 1, k + 15, 0);
		world.setBlock(i + 10, j + 1, k + 16, 0);
		world.setBlock(i + 10, j + 1, k + 17, 0);
		world.setBlock(i + 10, j + 1, k + 18, 0);
		world.setBlock(i + 10, j + 2, k + 0, 0);
		world.setBlock(i + 10, j + 2, k + 1, 0);
		world.setBlock(i + 10, j + 2, k + 2, 0);
		world.setBlock(i + 10, j + 2, k + 3, 0);
		world.setBlock(i + 10, j + 2, k + 4, 0);
		world.setBlock(i + 10, j + 2, k + 5, 0);
		world.setBlock(i + 10, j + 2, k + 6, 0);
		world.setBlock(i + 10, j + 2, k + 7, 0);
		world.setBlock(i + 10, j + 2, k + 8, 0);
		world.setBlock(i + 10, j + 2, k + 9, 0);
		world.setBlock(i + 10, j + 2, k + 10, 0);
		world.setBlock(i + 10, j + 2, k + 11, 0);
		world.setBlock(i + 10, j + 2, k + 12, 0);
		world.setBlock(i + 10, j + 2, k + 13, 0);
		world.setBlock(i + 10, j + 2, k + 14, 0);
		world.setBlock(i + 10, j + 2, k + 15, 0);
		world.setBlock(i + 10, j + 2, k + 16, 0);
		world.setBlock(i + 10, j + 2, k + 17, 0);
		world.setBlock(i + 10, j + 2, k + 18, 0);
		world.setBlock(i + 10, j + 3, k + 0, 0);
		world.setBlock(i + 10, j + 3, k + 1, 0);
		world.setBlock(i + 10, j + 3, k + 2, 0);
		world.setBlock(i + 10, j + 3, k + 3, 0);
		world.setBlock(i + 10, j + 3, k + 4, 0);
		world.setBlock(i + 10, j + 3, k + 5, 0);
		world.setBlockAndMetadata(i + 10, j + 3, k + 6, Block.stoneSingleSlab.blockID, 13);
		world.setBlock(i + 10, j + 3, k + 7, 0);
		world.setBlock(i + 10, j + 3, k + 8, 0);
		world.setBlock(i + 10, j + 3, k + 9, 0);
		world.setBlock(i + 10, j + 3, k + 10, 0);
		world.setBlock(i + 10, j + 3, k + 11, 0);
		world.setBlockAndMetadata(i + 10, j + 3, k + 12, Block.stoneSingleSlab.blockID, 13);
		world.setBlock(i + 10, j + 3, k + 13, 0);
		world.setBlock(i + 10, j + 3, k + 14, 0);
		world.setBlock(i + 10, j + 3, k + 15, 0);
		world.setBlock(i + 10, j + 3, k + 16, 0);
		world.setBlock(i + 10, j + 3, k + 17, 0);
		world.setBlock(i + 10, j + 3, k + 18, 0);
		world.setBlock(i + 10, j + 4, k + 0, 0);
		world.setBlock(i + 10, j + 4, k + 1, Block.stoneBrick.blockID);
		world.setBlock(i + 10, j + 4, k + 2, Block.stoneBrick.blockID);
		world.setBlock(i + 10, j + 4, k + 3, Block.stoneBrick.blockID);
		world.setBlock(i + 10, j + 4, k + 4, Block.stoneBrick.blockID);
		world.setBlock(i + 10, j + 4, k + 5, Block.stoneBrick.blockID);
		world.setBlock(i + 10, j + 4, k + 6, Block.stoneBrick.blockID);
		world.setBlock(i + 10, j + 4, k + 7, Block.stoneBrick.blockID);
		world.setBlock(i + 10, j + 4, k + 8, Block.stoneBrick.blockID);
		world.setBlock(i + 10, j + 4, k + 9, Block.stoneBrick.blockID);
		world.setBlock(i + 10, j + 4, k + 10, Block.stoneBrick.blockID);
		world.setBlock(i + 10, j + 4, k + 11, Block.stoneBrick.blockID);
		world.setBlock(i + 10, j + 4, k + 12, Block.stoneBrick.blockID);
		world.setBlock(i + 10, j + 4, k + 13, Block.stoneBrick.blockID);
		world.setBlock(i + 10, j + 4, k + 14, Block.stoneBrick.blockID);
		world.setBlock(i + 10, j + 4, k + 15, Block.stoneBrick.blockID);
		world.setBlock(i + 10, j + 4, k + 16, Block.stoneBrick.blockID);
		world.setBlock(i + 10, j + 4, k + 17, Block.stoneBrick.blockID);
		world.setBlock(i + 10, j + 4, k + 18, 0);
		world.setBlock(i + 10, j + 5, k + 0, 0);
		world.setBlock(i + 10, j + 5, k + 1, Block.thinGlass.blockID);
		world.setBlock(i + 10, j + 5, k + 2, Block.thinGlass.blockID);
		world.setBlock(i + 10, j + 5, k + 3, Block.thinGlass.blockID);
		world.setBlock(i + 10, j + 5, k + 4, Block.thinGlass.blockID);
		world.setBlock(i + 10, j + 5, k + 5, Block.thinGlass.blockID);
		world.setBlock(i + 10, j + 5, k + 6, Block.thinGlass.blockID);
		world.setBlock(i + 10, j + 5, k + 7, 0);
		world.setBlock(i + 10, j + 5, k + 8, 0);
		world.setBlock(i + 10, j + 5, k + 9, 0);
		world.setBlock(i + 10, j + 5, k + 10, 0);
		world.setBlock(i + 10, j + 5, k + 11, 0);
		world.setBlock(i + 10, j + 5, k + 12, Block.thinGlass.blockID);
		world.setBlock(i + 10, j + 5, k + 13, Block.thinGlass.blockID);
		world.setBlock(i + 10, j + 5, k + 14, Block.thinGlass.blockID);
		world.setBlock(i + 10, j + 5, k + 15, Block.thinGlass.blockID);
		world.setBlock(i + 10, j + 5, k + 16, Block.thinGlass.blockID);
		world.setBlock(i + 10, j + 5, k + 17, Block.thinGlass.blockID);
		world.setBlock(i + 10, j + 5, k + 18, 0);
		world.setBlock(i + 10, j + 6, k + 0, 0);
		world.setBlock(i + 10, j + 6, k + 1, Block.thinGlass.blockID);
		world.setBlock(i + 10, j + 6, k + 2, Block.thinGlass.blockID);
		world.setBlock(i + 10, j + 6, k + 3, Block.thinGlass.blockID);
		world.setBlock(i + 10, j + 6, k + 4, Block.thinGlass.blockID);
		world.setBlock(i + 10, j + 6, k + 5, Block.thinGlass.blockID);
		world.setBlock(i + 10, j + 6, k + 6, Block.thinGlass.blockID);
		world.setBlock(i + 10, j + 6, k + 7, 0);
		world.setBlock(i + 10, j + 6, k + 8, 0);
		world.setBlock(i + 10, j + 6, k + 9, 0);
		world.setBlock(i + 10, j + 6, k + 10, 0);
		world.setBlock(i + 10, j + 6, k + 11, 0);
		world.setBlock(i + 10, j + 6, k + 12, Block.thinGlass.blockID);
		world.setBlock(i + 10, j + 6, k + 13, Block.thinGlass.blockID);
		world.setBlock(i + 10, j + 6, k + 14, Block.thinGlass.blockID);
		world.setBlock(i + 10, j + 6, k + 15, Block.thinGlass.blockID);
		world.setBlock(i + 10, j + 6, k + 16, Block.thinGlass.blockID);
		world.setBlock(i + 10, j + 6, k + 17, Block.thinGlass.blockID);
		world.setBlock(i + 10, j + 6, k + 18, 0);
		world.setBlockAndMetadata(i + 10, j + 7, k + 0, Block.stairsStoneBrickSmooth.blockID, 2);
		world.setBlockAndMetadata(i + 10, j + 7, k + 1, Block.stairsStoneBrickSmooth.blockID, 1);
		world.setBlockAndMetadata(i + 10, j + 7, k + 2, Block.stairsStoneBrickSmooth.blockID, 1);
		world.setBlockAndMetadata(i + 10, j + 7, k + 3, Block.stairsStoneBrickSmooth.blockID, 1);
		world.setBlockAndMetadata(i + 10, j + 7, k + 4, Block.stairsStoneBrickSmooth.blockID, 1);
		world.setBlockAndMetadata(i + 10, j + 7, k + 5, Block.stairsStoneBrickSmooth.blockID, 1);
		world.setBlockAndMetadata(i + 10, j + 7, k + 6, Block.stairsStoneBrickSmooth.blockID, 2);
		world.setBlock(i + 10, j + 7, k + 7, 0);
		world.setBlock(i + 10, j + 7, k + 8, 0);
		world.setBlock(i + 10, j + 7, k + 9, 0);
		world.setBlock(i + 10, j + 7, k + 10, 0);
		world.setBlock(i + 10, j + 7, k + 11, 0);
		world.setBlockAndMetadata(i + 10, j + 7, k + 12, Block.stairsStoneBrickSmooth.blockID, 3);
		world.setBlockAndMetadata(i + 10, j + 7, k + 13, Block.stairsStoneBrickSmooth.blockID, 1);
		world.setBlockAndMetadata(i + 10, j + 7, k + 14, Block.stairsStoneBrickSmooth.blockID, 1);
		world.setBlockAndMetadata(i + 10, j + 7, k + 15, Block.stairsStoneBrickSmooth.blockID, 1);
		world.setBlockAndMetadata(i + 10, j + 7, k + 16, Block.stairsStoneBrickSmooth.blockID, 1);
		world.setBlockAndMetadata(i + 10, j + 7, k + 17, Block.stairsStoneBrickSmooth.blockID, 1);
		world.setBlockAndMetadata(i + 10, j + 7, k + 18, Block.stairsStoneBrickSmooth.blockID, 1);
		world.setBlock(i + 10, j + 8, k + 0, 0);
		world.setBlock(i + 10, j + 8, k + 1, 0);
		world.setBlock(i + 10, j + 8, k + 2, 0);
		world.setBlock(i + 10, j + 8, k + 3, 0);
		world.setBlock(i + 10, j + 8, k + 4, 0);
		world.setBlock(i + 10, j + 8, k + 5, 0);
		world.setBlock(i + 10, j + 8, k + 6, 0);
		world.setBlockAndMetadata(i + 10, j + 8, k + 7, Block.stairsStoneBrickSmooth.blockID, 2);
		world.setBlock(i + 10, j + 8, k + 8, Block.stoneBrick.blockID);
		world.setBlock(i + 10, j + 8, k + 9, Block.stoneBrick.blockID);
		world.setBlock(i + 10, j + 8, k + 10, Block.stoneBrick.blockID);
		world.setBlockAndMetadata(i + 10, j + 8, k + 11, Block.stairsStoneBrickSmooth.blockID, 3);
		world.setBlock(i + 10, j + 8, k + 12, 0);
		world.setBlock(i + 10, j + 8, k + 13, 0);
		world.setBlock(i + 10, j + 8, k + 14, 0);
		world.setBlock(i + 10, j + 8, k + 15, 0);
		world.setBlock(i + 10, j + 8, k + 16, 0);
		world.setBlock(i + 10, j + 8, k + 17, 0);
		world.setBlock(i + 10, j + 8, k + 18, 0);
		world.setBlock(i + 11, j + 0, k + 0, 0);
		world.setBlock(i + 11, j + 0, k + 1, 0);
		world.setBlock(i + 11, j + 0, k + 2, 0);
		world.setBlock(i + 11, j + 0, k + 3, 0);
		world.setBlock(i + 11, j + 0, k + 4, 0);
		world.setBlock(i + 11, j + 0, k + 5, Block.grass.blockID);
		world.setBlock(i + 11, j + 0, k + 6, Block.dirt.blockID);
		world.setBlock(i + 11, j + 0, k + 7, Block.grass.blockID);
		world.setBlock(i + 11, j + 0, k + 8, Block.grass.blockID);
		world.setBlock(i + 11, j + 0, k + 9, Block.grass.blockID);
		world.setBlock(i + 11, j + 0, k + 10, Block.grass.blockID);
		world.setBlock(i + 11, j + 0, k + 11, Block.grass.blockID);
		world.setBlock(i + 11, j + 0, k + 12, Block.dirt.blockID);
		world.setBlock(i + 11, j + 0, k + 13, Block.grass.blockID);
		world.setBlock(i + 11, j + 0, k + 14, 0);
		world.setBlock(i + 11, j + 0, k + 15, 0);
		world.setBlock(i + 11, j + 0, k + 16, 0);
		world.setBlock(i + 11, j + 0, k + 17, 0);
		world.setBlock(i + 11, j + 0, k + 18, 0);
		world.setBlock(i + 11, j + 1, k + 0, 0);
		world.setBlock(i + 11, j + 1, k + 1, 0);
		world.setBlock(i + 11, j + 1, k + 2, 0);
		world.setBlock(i + 11, j + 1, k + 3, 0);
		world.setBlock(i + 11, j + 1, k + 4, 0);
		world.setBlock(i + 11, j + 1, k + 5, 0);
		world.setBlock(i + 11, j + 1, k + 6, Block.stoneBrick.blockID);
		world.setBlock(i + 11, j + 1, k + 8, 0);
		world.setBlock(i + 11, j + 1, k + 9, 0);
		world.setBlock(i + 11, j + 1, k + 10, 0);
		world.setBlock(i + 11, j + 1, k + 12, Block.stoneBrick.blockID);
		world.setBlock(i + 11, j + 1, k + 13, 0);
		world.setBlock(i + 11, j + 1, k + 14, 0);
		world.setBlock(i + 11, j + 1, k + 15, 0);
		world.setBlock(i + 11, j + 1, k + 16, 0);
		world.setBlock(i + 11, j + 1, k + 17, 0);
		world.setBlock(i + 11, j + 1, k + 18, 0);
		world.setBlock(i + 11, j + 2, k + 0, 0);
		world.setBlock(i + 11, j + 2, k + 1, 0);
		world.setBlock(i + 11, j + 2, k + 2, 0);
		world.setBlock(i + 11, j + 2, k + 3, 0);
		world.setBlock(i + 11, j + 2, k + 4, 0);
		world.setBlock(i + 11, j + 2, k + 5, 0);
		world.setBlock(i + 11, j + 2, k + 6, Block.stoneBrick.blockID);
		world.setBlock(i + 11, j + 2, k + 8, 0);
		world.setBlock(i + 11, j + 2, k + 9, 0);
		world.setBlock(i + 11, j + 2, k + 10, 0);
		world.setBlock(i + 11, j + 2, k + 12, Block.stoneBrick.blockID);
		world.setBlock(i + 11, j + 2, k + 13, 0);
		world.setBlock(i + 11, j + 2, k + 14, 0);
		world.setBlock(i + 11, j + 2, k + 15, 0);
		world.setBlock(i + 11, j + 2, k + 16, 0);
		world.setBlock(i + 11, j + 2, k + 17, 0);
		world.setBlock(i + 11, j + 2, k + 18, 0);
		world.setBlock(i + 11, j + 3, k + 0, 0);
		world.setBlock(i + 11, j + 3, k + 1, 0);
		world.setBlock(i + 11, j + 3, k + 2, 0);
		world.setBlock(i + 11, j + 3, k + 3, 0);
		world.setBlock(i + 11, j + 3, k + 4, 0);
		world.setBlock(i + 11, j + 3, k + 5, 0);
		world.setBlock(i + 11, j + 3, k + 6, Block.stoneBrick.blockID);
		world.setBlock(i + 11, j + 3, k + 8, 0);
		world.setBlock(i + 11, j + 3, k + 9, 0);
		world.setBlock(i + 11, j + 3, k + 10, 0);
		world.setBlock(i + 11, j + 3, k + 12, Block.stoneBrick.blockID);
		world.setBlock(i + 11, j + 3, k + 13, 0);
		world.setBlock(i + 11, j + 3, k + 14, 0);
		world.setBlock(i + 11, j + 3, k + 15, 0);
		world.setBlock(i + 11, j + 3, k + 16, 0);
		world.setBlock(i + 11, j + 3, k + 17, 0);
		world.setBlock(i + 11, j + 3, k + 18, 0);
		world.setBlock(i + 11, j + 4, k + 0, 0);
		world.setBlock(i + 11, j + 4, k + 1, 0);
		world.setBlock(i + 11, j + 4, k + 2, 0);
		world.setBlock(i + 11, j + 4, k + 3, 0);
		world.setBlock(i + 11, j + 4, k + 4, 0);
		world.setBlock(i + 11, j + 4, k + 5, 0);
		world.setBlock(i + 11, j + 4, k + 6, Block.stoneBrick.blockID);
		world.setBlock(i + 11, j + 4, k + 8, Block.stoneBrick.blockID);
		world.setBlock(i + 11, j + 4, k + 9, Block.stoneBrick.blockID);
		world.setBlock(i + 11, j + 4, k + 10, Block.stoneBrick.blockID);
		world.setBlock(i + 11, j + 4, k + 12, Block.stoneBrick.blockID);
		world.setBlock(i + 11, j + 4, k + 13, 0);
		world.setBlock(i + 11, j + 4, k + 14, 0);
		world.setBlock(i + 11, j + 4, k + 15, 0);
		world.setBlock(i + 11, j + 4, k + 16, 0);
		world.setBlock(i + 11, j + 4, k + 17, 0);
		world.setBlock(i + 11, j + 4, k + 18, 0);
		world.setBlock(i + 11, j + 5, k + 0, 0);
		world.setBlock(i + 11, j + 5, k + 1, 0);
		world.setBlock(i + 11, j + 5, k + 2, 0);
		world.setBlock(i + 11, j + 5, k + 3, 0);
		world.setBlock(i + 11, j + 5, k + 4, 0);
		world.setBlock(i + 11, j + 5, k + 5, 0);
		world.setBlock(i + 11, j + 5, k + 6, Block.stoneBrick.blockID);
		world.setBlock(i + 11, j + 5, k + 8, 0);
		world.setBlock(i + 11, j + 5, k + 9, 0);
		world.setBlock(i + 11, j + 5, k + 10, 0);
		world.setBlock(i + 11, j + 5, k + 12, Block.stoneBrick.blockID);
		world.setBlock(i + 11, j + 5, k + 13, 0);
		world.setBlock(i + 11, j + 5, k + 14, 0);
		world.setBlock(i + 11, j + 5, k + 15, 0);
		world.setBlock(i + 11, j + 5, k + 16, 0);
		world.setBlock(i + 11, j + 5, k + 17, 0);
		world.setBlock(i + 11, j + 5, k + 18, 0);
		world.setBlock(i + 11, j + 6, k + 0, 0);
		world.setBlock(i + 11, j + 6, k + 1, 0);
		world.setBlock(i + 11, j + 6, k + 2, 0);
		world.setBlock(i + 11, j + 6, k + 3, 0);
		world.setBlock(i + 11, j + 6, k + 4, 0);
		world.setBlock(i + 11, j + 6, k + 5, 0);
		world.setBlock(i + 11, j + 6, k + 6, Block.stoneBrick.blockID);
		world.setBlock(i + 11, j + 6, k + 8, 0);
		world.setBlock(i + 11, j + 6, k + 9, 0);
		world.setBlock(i + 11, j + 6, k + 10, 0);
		world.setBlock(i + 11, j + 6, k + 12, Block.stoneBrick.blockID);
		world.setBlock(i + 11, j + 6, k + 13, 0);
		world.setBlock(i + 11, j + 6, k + 14, 0);
		world.setBlock(i + 11, j + 6, k + 15, 0);
		world.setBlock(i + 11, j + 6, k + 16, 0);
		world.setBlock(i + 11, j + 6, k + 17, 0);
		world.setBlock(i + 11, j + 6, k + 18, 0);
		world.setBlock(i + 11, j + 7, k + 0, 0);
		world.setBlock(i + 11, j + 7, k + 1, 0);
		world.setBlock(i + 11, j + 7, k + 2, 0);
		world.setBlock(i + 11, j + 7, k + 3, 0);
		world.setBlock(i + 11, j + 7, k + 4, 0);
		world.setBlock(i + 11, j + 7, k + 5, 0);
		world.setBlockAndMetadata(i + 11, j + 7, k + 6, Block.stairsStoneBrickSmooth.blockID, 2);
		world.setBlock(i + 11, j + 7, k + 7, 0);
		world.setBlock(i + 11, j + 7, k + 8, 0);
		world.setBlock(i + 11, j + 7, k + 9, 0);
		world.setBlock(i + 11, j + 7, k + 10, 0);
		world.setBlock(i + 11, j + 7, k + 11, 0);
		world.setBlockAndMetadata(i + 11, j + 7, k + 12, Block.stairsStoneBrickSmooth.blockID, 3);
		world.setBlock(i + 11, j + 7, k + 13, 0);
		world.setBlock(i + 11, j + 7, k + 14, 0);
		world.setBlock(i + 11, j + 7, k + 15, 0);
		world.setBlock(i + 11, j + 7, k + 16, 0);
		world.setBlock(i + 11, j + 7, k + 17, 0);
		world.setBlock(i + 11, j + 7, k + 18, 0);
		world.setBlock(i + 11, j + 8, k + 0, 0);
		world.setBlock(i + 11, j + 8, k + 1, 0);
		world.setBlock(i + 11, j + 8, k + 2, 0);
		world.setBlock(i + 11, j + 8, k + 3, 0);
		world.setBlock(i + 11, j + 8, k + 4, 0);
		world.setBlock(i + 11, j + 8, k + 5, 0);
		world.setBlock(i + 11, j + 8, k + 6, 0);
		world.setBlockAndMetadata(i + 11, j + 8, k + 7, Block.stairsStoneBrickSmooth.blockID, 2);
		world.setBlockAndMetadata(i + 11, j + 8, k + 8, Block.stairsStoneBrickSmooth.blockID, 1);
		world.setBlockAndMetadata(i + 11, j + 8, k + 9, Block.stairsStoneBrickSmooth.blockID, 1);
		world.setBlockAndMetadata(i + 11, j + 8, k + 10, Block.stairsStoneBrickSmooth.blockID, 1);
		world.setBlockAndMetadata(i + 11, j + 8, k + 11, Block.stairsStoneBrickSmooth.blockID, 1);
		world.setBlock(i + 11, j + 8, k + 12, 0);
		world.setBlock(i + 11, j + 8, k + 13, 0);
		world.setBlock(i + 11, j + 8, k + 14, 0);
		world.setBlock(i + 11, j + 8, k + 15, 0);
		world.setBlock(i + 11, j + 8, k + 16, 0);
		world.setBlock(i + 11, j + 8, k + 17, 0);
		world.setBlock(i + 11, j + 8, k + 18, 0);
		world.setBlock(i + 12, j + 0, k + 0, 0);
		world.setBlock(i + 12, j + 0, k + 1, 0);
		world.setBlock(i + 12, j + 0, k + 2, 0);
		world.setBlock(i + 12, j + 0, k + 3, 0);
		world.setBlock(i + 12, j + 0, k + 4, 0);
		world.setBlock(i + 12, j + 0, k + 5, Block.grass.blockID);
		world.setBlock(i + 12, j + 0, k + 6, Block.stone.blockID);
		world.setBlock(i + 12, j + 0, k + 7, Block.dirt.blockID);
		world.setBlock(i + 12, j + 0, k + 8, Block.stone.blockID);
		world.setBlock(i + 12, j + 0, k + 9, Block.grass.blockID);
		world.setBlock(i + 12, j + 0, k + 10, Block.stone.blockID);
		world.setBlock(i + 12, j + 0, k + 11, Block.dirt.blockID);
		world.setBlock(i + 12, j + 0, k + 12, Block.stone.blockID);
		world.setBlock(i + 12, j + 0, k + 13, Block.grass.blockID);
		world.setBlock(i + 12, j + 0, k + 14, 0);
		world.setBlock(i + 12, j + 0, k + 15, 0);
		world.setBlock(i + 12, j + 0, k + 16, 0);
		world.setBlock(i + 12, j + 0, k + 17, 0);
		world.setBlock(i + 12, j + 0, k + 18, 0);
		world.setBlock(i + 12, j + 1, k + 0, 0);
		world.setBlock(i + 12, j + 1, k + 1, 0);
		world.setBlock(i + 12, j + 1, k + 2, 0);
		world.setBlock(i + 12, j + 1, k + 3, 0);
		world.setBlock(i + 12, j + 1, k + 4, 0);
		world.setBlock(i + 12, j + 1, k + 5, 0);
		world.setBlock(i + 12, j + 1, k + 6, Block.stoneBrick.blockID);
		world.setBlock(i + 12, j + 1, k + 7, Block.stoneBrick.blockID);
		world.setBlock(i + 12, j + 1, k + 8, 0);
